Workbook

Sheet SUMMARY
A1: SEPTEMBER 2026 DAYRATE PAYMENT SCHEDULE
A2: COMPANY | B2: HEADCOUNT | C2: GROSS AMOUNT | D2: AMOUNT PAYABLE
A3: DLE | B3: 180 | C3: 63654567 | D3: 60471839
A4: DLPC | B4: 7 | C4: 1490518.8 | D4: 1415992.8
A5: Total | B5: 187 | C5: 65145086 | D5: 61887831

Sheet DLE
A1: Contractor Code | B1: First Name | C1: Last Name | D1: Job Title | E1: Location | F1: Daily Rate | G1: AGE | H1: Gender | I1: Total Weekday | J1: Weekday OVT | K1: Total Saturday | L1: Total Sunday | M1: Night Worked | N1: Wkd Earning | O1: Wkd Ovt Amt | P1: Sat Ovt Amt | Q1: Sun Ovt Amt | R1: Night Amt | S1: Meal Allowance | T1: Transport | U1: Site Allowance | V1: TCM Meal | W1: TCM TRANSPORT | X1: Arrears | Y1: Total Earnings | Z1: WHT | AA1: Gross Amount | AB1: Amount Payable
A2: C0129 | B2: AGWU OKWARA | C2: KALU | D2: GRINDER/PWHT ASSISTANT | E2: IDI_ORO | F2: 13050 | G2: 63 | H2: M | I2: 21 | K2: 22.4 | L2: 1 | N2: 274050 | P2: 54810 | Q2: 3262.5 | S2: 10500 | Y2: 371985 | Z2: 18599.25 | AA2: 371985 | AB2: 353385.75
A3: C0293 | B3: OLAKUNLE | C3: OLANIYAN | D3: ELECTRICIAN | E3: IDI_ORO | F3: 10250 | G3: 57 | H3: M | I3: 21 | J3: 2 | K3: 32 | L3: 60 | M3: 5 | N3: 215250 | O3: 3843.75 | P3: 61500 | Q3: 153750 | R3: 7500 | S3: 10500 | Y3: 475406.25 | Z3: 23770.31 | AA3: 475406.25 | AB3: 451635.94
A4: C0585 | B4: BELLO | C4: FEMI | D4: SCAFFOLDER SUPERVISOR | E4: IDI_ORO | F4: 16200 | G4: 61 | H4: M | I4: 21 | K4: 19.6 | L4: 9.3 | N4: 340200 | P4: 59535 | Q4: 37665 | S4: 10500 | Y4: 451950 | Z4: 22597.5 | AA4: 451950 | AB4: 429352.5
A5: C0695 | B5: JULIUS | C5: AWOYEMI | D5: ELECTRICIAN | E5: AGEGE | F5: 10250 | G5: 48 | H5: M | I5: 21 | J5: 13.6 | K5: 28 | L5: 39 | N5: 215250 | O5: 26137.5 | P5: 53812.5 | Q5: 99937.5 | S5: 10500 | Y5: 423575 | Z5: 21178.75 | AA5: 423575 | AB5: 402396.25
A6: C0974 | B6: STEPHEN | C6: ETUERI | D6: MACHINE SHOP SUPRITENDENT | E6: IDI_ORO | F6: 17850 | G6: 78 | H6: M | I6: 21 | L6: 1 | N6: 374850 | Q6: 4462.5 | S6: 10500 | Y6: 425512.5 | Z6: 21275.63 | AA6: 425512.5 | AB6: 404236.87
A7: C1001 | B7: JIMOH | C7: GBADAMOSI | D7: BLASTER& PAINTER SUPERVISOR | E7: AGEGE | F7: 19500 | G7: 57 | H7: M | I7: 20 | K7: 7 | N7: 390000 | P7: 25593.75 | S7: 10000 | Y7: 459718.75 | Z7: 22985.94 | AA7: 459718.75 | AB7: 436732.81
A8: C1035 | B8: DONATUS | C8: EJEH | D8: RIGGER | E8: IDI_ORO | F8: 13150 | G8: 51 | H8: M | I8: 21 | K8: 17 | L8: 2 | N8: 276150 | P8: 41915.63 | Q8: 6575 | S8: 10500 | Y8: 364728.13 | Z8: 18236.41 | AA8: 364728.13 | AB8: 346491.72
A9: C1065 | B9: VINCENT | C9: OGHENERIE | D9: FITTER 1 | E9: IDI_ORO | F9: 14050 | G9: 62 | H9: M | I9: 21 | K9: 24.2 | L9: 1 | N9: 295050 | P9: 63751.88 | Q9: 3512.5 | S9: 10000 | Y9: 403926.88 | Z9: 20196.34 | AA9: 403926.88 | AB9: 383730.54
A10: C1078 | B10: MATHIAS | C10: LUKPATA | D10: FORKLIFT OPERATOR | E10: AGEGE | F10: 12750 | G10: 46 | H10: M | I10: 21 | K10: 30 | L10: 1 | N10: 267750 | P10: 71718.75 | Q10: 3187.5 | S10: 10500 | Y10: 375468.75 | Z10: 18773.44 | AA10: 375468.75 | AB10: 356695.31
A11: C1096 | B11: DUROJAYE | C11: ADEDOYIN | D11: MECHANIC | E11: AGEGE | F11: 10250 | G11: 43 | H11: M | I11: 21 | J11: 12 | K11: 28 | L11: 35 | N11: 215250 | O11: 23062.5 | P11: 53812.5 | Q11: 89687.5 | S11: 10500 | Y11: 410250 | Z11: 20512.5 | AA11: 410250 | AB11: 389737.5
A12: C1144 | B12: CHRIS | C12: OGWUA | D12: WELDER | E12: IDI - IDI_ORO | F12: 13550 | G12: 44 | H12: M | I12: 3 | N12: 40650 | S12: 1500 | Y12: 42150 | Z12: 2107.5 | AA12: 42150 | AB12: 40042.5
A13: C1162 | B13: ADEWALE | C13: ADEKOYA | D13: 6GR (SMAW & GTAW) | E13: IDI_ORO | F13: 23500 | G13: 55 | H13: M | I13: 21 | J13: 8.7 | K13: 9 | N13: 493500 | O13: 38334.37 | P13: 39656.25 | S13: 10500 | Y13: 623115.62 | Z13: 31155.78 | AA13: 623115.62 | AB13: 591959.84
A14: C1220 | B14: DANIEL | C14: NWODO | D14: TACK WELDER | E14: AGEGE | F14: 11575 | G14: 55 | H14: M | I14: 21 | K14: 26 | L14: 4 | N14: 243075 | P14: 56428.13 | Q14: 11575 | S14: 10500 | Y14: 350226.26 | Z14: 17511.31 | AA14: 350226.26 | AB14: 332714.95
A15: C1229 | B15: SHITTU | C15: OLAWALE | D15: WELDER | E15: AGEGE | F15: 18150 | G15: 49 | H15: M | L15: 13 | Q15: 58987.5 | Y15: 58987.5 | Z15: 2949.38 | AA15: 58987.5 | AB15: 56038.12
A16: C1491 | B16: NNAMDI | C16: VINCENT | D16: GRINDER | E16: IDI_ORO | F16: 10250 | G16: 46 | H16: M | I16: 21 | K16: 20.9 | L16: 8 | N16: 215250 | P16: 40167.19 | Q16: 20500 | S16: 10500 | Y16: 309479.69 | Z16: 15473.98 | AA16: 309479.69 | AB16: 294005.71
A17: C1533 | B17: VINCENT | C17: OKEKE | D17: CRANE/RIGGER SUPERVISOR | E17: IDI_ORO | F17: 16000 | G17: 49 | H17: M | I17: 21 | K17: 18.8 | L17: 1 | N17: 336000 | P17: 56400 | Q17: 4000 | S17: 10500 | Y17: 442900 | Z17: 22145 | AA17: 442900 | AB17: 420755
A18: C1544 | B18: JOSEPH | C18: ADENIYI | D18: LIFTNG SUP. | E18: AGEGE | F18: 16200 | G18: 42 | H18: M | I18: 6 | K18: 13.2 | L18: 13 | N18: 97200 | P18: 40095 | Q18: 52650 | S18: 3000 | Y18: 246405 | Z18: 12320.25 | AA18: 246405 | AB18: 234084.75
A19: C1607 | B19: CHUKWUDUMEBI | C19: OJIKA | D19: FITTER / CNC OPR | E19: AGEGE | F19: 15100 | G19: 37 | H19: M | I19: 21 | K19: 3 | N19: 317100 | P19: 8493.75 | S19: 10500 | Y19: 362518.75 | Z19: 18125.94 | AA19: 362518.75 | AB19: 344392.81
A20: C1612 | B20: RICHARD | C20: MBAMARA | D20: HYDROTESTER | E20: IDI_ORO | F20: 16000 | G20: 55 | H20: M | I20: 21 | J20: 7.7 | K20: 7 | N20: 336000 | O20: 23100 | P20: 21000 | S20: 10500 | Y20: 418600 | Z20: 20930 | AA20: 418600 | AB20: 397670
A21: C1686 | B21: MICAH | C21: FRED | D21: WELDER | E21: AGEGE | F21: 16700 | G21: 36 | H21: M | L21: 18 | Q21: 75150 | Y21: 75150 | Z21: 3757.5 | AA21: 75150 | AB21: 71392.5
A22: C1705 | B22: MATTHEW | C22: ROTIMI | D22: MECHANIC | E22: IDI_ORO | F22: 10250 | G22: 47 | H22: M | I22: 21 | K22: 24 | L22: 15 | N22: 215250 | P22: 46125 | Q22: 38437.5 | S22: 10500 | Y22: 328250 | Z22: 16412.5 | AA22: 328250 | AB22: 311837.5
A23: C1720 | B23: ADANOU | C23: RAYMOND | D23: FITTER 1 | E23: AGEGE | F23: 14050 | G23: 55 | H23: M | I23: 21 | K23: 21 | N23: 295050 | P23: 55321.88 | S23: 10500 | Y23: 364384.38 | Z23: 18219.22 | AA23: 364384.38 | AB23: 346165.16
A24: C1728 | B24: MOHAMMED | C24: IBRAHIM | D24: 6GR (SMAW & GTAW) | E24: IDI_ORO | F24: 23500 | G24: 38 | H24: M | I24: 11 | K24: 8 | N24: 258500 | P24: 35250 | S24: 5500 | Y24: 346250 | Z24: 17312.5 | AA24: 346250 | AB24: 328937.5
A25: C1736 | B25: MICHAEL | C25: JEROME | D25: 6G WELDER | E25: IDI_ORO | F25: 16700 | G25: 55 | H25: M | I25: 21 | K25: 9 | N25: 350700 | P25: 28181.25 | S25: 10500 | Y25: 426956.25 | Z25: 21347.81 | AA25: 426956.25 | AB25: 405608.44
A26: C1771 | B26: KEHINDE | C26: BADEJO | D26: RIGGER | E26: AGEGE | F26: 13150 | G26: 45 | H26: M | I26: 21 | K26: 28 | L26: 1 | N26: 276150 | P26: 69037.5 | Q26: 3287.5 | S26: 10500 | Y26: 381987.5 | Z26: 19099.38 | AA26: 381987.5 | AB26: 362888.12
A27: C1772 | B27: IDOWU | C27: GANIYU | D27: CRANE OPERATOR & RIGGER | E27: AGEGE | F27: 13150 | G27: 58 | H27: M | I27: 21 | K27: 32 | L27: 1 | N27: 276150 | P27: 78900 | Q27: 3287.5 | S27: 10500 | Y27: 391850 | Z27: 19592.5 | AA27: 391850 | AB27: 372257.5
A28: C1775 | B28: MOMODU | C28: BASHRU | D28: GRINDER | E28: AGEGE | F28: 10250 | G28: 45 | H28: M | I28: 21 | K28: 28 | L28: 4 | N28: 215250 | P28: 53812.5 | Q28: 10250 | S28: 10500 | Y28: 310312.5 | Z28: 15515.63 | AA28: 310312.5 | AB28: 294796.87
A29: C1779 | B29: KENNEDY | C29: EBUNO | D29: SMAW&GTAW (CS) WELDER | E29: IDI_ORO | F29: 23500 | G29: 61 | H29: M | I29: 21 | J29: 2 | K29: 9 | N29: 493500 | O29: 8812.5 | P29: 39656.25 | S29: 10500 | Y29: 605343.75 | Z29: 30267.19 | AA29: 605343.75 | AB29: 575076.56
A30: C1783 | B30: OLUGBENGA | C30: DARAMOLA | D30: FITTER | E30: AGEGE | F30: 14050 | G30: 47 | H30: M | I30: 21 | K30: 28 | N30: 295050 | P30: 73762.5 | S30: 10500 | Y30: 382825 | Z30: 19141.25 | AA30: 382825 | AB30: 363683.75
A31: C1788 | B31: JONAH EMEWU | C31: SAMUEL | D31: FITTER | E31: IDI_ORO | F31: 14050 | G31: 49 | H31: M | I31: 21 | K31: 19.2 | L31: 1 | N31: 295050 | P31: 50580 | Q31: 3512.5 | S31: 10500 | Y31: 391255 | Z31: 19562.75 | AA31: 391255 | AB31: 371692.25
A32: C1789 | B32: MONDAY | C32: MBOCHI | D32: FITTER | E32: IDI_ORO | F32: 14050 | G32: 47 | H32: M | I32: 8 | J32: 4 | K32: 22 | L32: 1 | N32: 112400 | O32: 10537.5 | P32: 57956.25 | Q32: 3512.5 | S32: 4000 | Y32: 228800 | Z32: 11440 | AA32: 228800 | AB32: 217360
A33: C1793 | B33: SAVIOUR UDO | C33: ITORO | D33: WELDER | E33: AGEGE | F33: 13550 | G33: 37 | H33: M | I33: 21 | K33: 28 | L33: 4 | N33: 284550 | P33: 71137.5 | Q33: 13550 | S33: 10500 | Y33: 423097.5 | Z33: 21154.88 | AA33: 423097.5 | AB33: 401942.62
A34: C1804 | B34: UMA | C34: KALU | D34: GRINDER | E34: AGEGE | F34: 10250 | G34: 57 | H34: M | I34: 21 | K34: 32 | L34: 4 | N34: 215250 | P34: 61500 | Q34: 10250 | S34: 10500 | Y34: 318000 | Z34: 15900 | AA34: 318000 | AB34: 302100
A35: C1820 | B35: SUNDAY | C35: OKORO | D35: FITTER | E35: IDI_ORO | F35: 14050 | G35: 56 | H35: M | I35: 21 | K35: 19.2 | L35: 1 | N35: 295050 | P35: 50580 | Q35: 3512.5 | S35: 10500 | Y35: 387742.5 | Z35: 19387.13 | AA35: 387742.5 | AB35: 368355.37
A36: C1823 | B36: MATTHEW | C36: EGBUJOR | D36: GRINDER | E36: IDI_ORO | F36: 10250 | G36: 61 | H36: M | I36: 21 | K36: 23.6 | L36: 1 | N36: 215250 | P36: 45356.25 | Q36: 2562.5 | S36: 10500 | Y36: 296731.25 | Z36: 14836.56 | AA36: 296731.25 | AB36: 281894.69
A37: C1824 | B37: ALPHONSUS | C37: ADAOWO | D37: FITTER | E37: IDI_ORO | F37: 14050 | G37: 45 | H37: M | I37: 20 | K37: 20.2 | L37: 1 | N37: 281000 | P37: 53214.38 | Q37: 3512.5 | S37: 10000 | Y37: 375826.88 | Z37: 18791.34 | AA37: 375826.88 | AB37: 357035.54
A38: C1840 | B38: FRIDAY | C38: ISINGUZO | D38: GRINDER | E38: IDI_ORO | F38: 10250 | G38: 59 | H38: M | I38: 21 | K38: 26.6 | L38: 1 | N38: 215250 | P38: 51121.88 | Q38: 2562.5 | S38: 10500 | Y38: 302496.88 | Z38: 15124.84 | AA38: 302496.88 | AB38: 287372.04
A39: C1849 | B39: SUCCESS JAMES | C39: OKORIE | D39: FACTORY CLEANER | E39: IDI_ORO | F39: 8600 | G39: 35 | H39: M | I39: 21 | K39: 19 | L39: 1 | N39: 180600 | P39: 30637.5 | Q39: 2150 | S39: 10500 | Y39: 243237.5 | Z39: 12161.88 | AA39: 243237.5 | AB39: 231075.62
A40: C1870 | B40: JOHN | C40: OHIEMBOR | D40: PREP. SUP | E40: AGEGE | F40: 16200 | G40: 68 | H40: M | I40: 21 | K40: 36 | N40: 340200 | P40: 109350 | S40: 10500 | Y40: 464100 | Z40: 23205 | AA40: 464100 | AB40: 440895
...

Sheet DLPC
A1: Contractor Code | B1: First Name | C1: Last Name | D1: Job Title | E1: Daily Rate | F1: Age | G1: Gender | H1: Total Weekday | I1: Weekday OVT | J1: Total Saturday | K1: Total Sunday | L1: Public Holiday | M1: Night Worked | N1: Wkd Earning | O1: Wkd Ovt Amt | P1: Sat Ovt Amt | Q1: Sun Ovt Amt | R1: PH Amt | S1: Night Amt | T1: Meal Allowance | U1: Transport | V1: Total Earnings | W1: WHT | X1: Gross Amount | Y1: Amount Payable
A2: C2394 | B2: IDOWU | C2: HAMMED | D2: KETTLE | E2: 9500 | F2: 34 | G2: M | H2: 21 | J2: 1 | L2: 1 | N2: 199500 | P2: 1781.25 | R2: 2375 | T2: 10500 | V2: 214156.25 | W2: 10707.81 | X2: 214156.25 | Y2: 203448.44
A3: C2396 | B3: MUSBAU | C3: AKINDELE | D3: KETTLE | E3: 9500 | F3: 36 | G3: M | H3: 21 | J3: 1 | L3: 1 | N3: 199500 | P3: 1781.25 | R3: 2375 | T3: 10500 | V3: 214156.25 | W3: 10707.81 | X3: 214156.25 | Y3: 203448.44
A4: C2408 | B4: LAWRENCE | C4: ANTHONY | D4: SKIMMER TECHNICIAN | E4: 10000 | F4: 47 | G4: M | H4: 21 | J4: 1 | L4: 1 | N4: 210000 | P4: 1875 | R4: 2500 | T4: 10500 | V4: 224875 | W4: 11243.75 | X4: 224875 | Y4: 213631.25
A5: C2443 | B5: ADEBIYI | C5: GANIYU | D5: KETTLE | E5: 9500 | F5: 37 | G5: M | H5: 21 | J5: 1 | L5: 1 | N5: 199500 | P5: 1781.25 | R5: 2375 | T5: 10500 | V5: 214156.25 | W5: 10707.81 | X5: 214156.25 | Y5: 203448.44
A6: C2506 | B6: MICHAEL | C6: ONOJA | D6: KETTLE | E6: 9500 | F6: 29 | G6: M | H6: 21 | J6: 1 | L6: 1 | N6: 199500 | P6: 1781.25 | R6: 2375 | T6: 10500 | V6: 214156.25 | W6: 10707.81 | X6: 214156.25 | Y6: 203448.44
A7: C2512 | B7: SUNDAY | C7: OVAT | D7: QC ASSISTANCE | E7: 8600 | F7: 25 | G7: M | H7: 21 | J7: 1 | L7: 1 | N7: 180600 | P7: 1612.5 | R7: 2150 | T7: 10500 | V7: 194862.5 | W7: 9743.13 | X7: 194862.5 | Y7: 185119.37
A8: C2522 | B8: JAMIU | C8: RASAK | D8: KETTLE | E8: 9500 | F8: 42 | G8: M | H8: 21 | J8: 1 | L8: 1 | N8: 199500 | P8: 1781.25 | R8: 2375 | T8: 10500 | V8: 214156.25 | W8: 10707.81 | X8: 214156.25 | Y8: 203448.44
A9: =SUBTOTAL(103,Table52[Contractor Code]) -> 7 | E9: =SUBTOTAL(109,Table52[Daily Rate]) -> 66100 | H9: =SUBTOTAL(109,Table52[Total Weekday]) -> 147 | I9: =SUBTOTAL(109,Table52[Weekday OVT]) -> 0 | J9: =SUBTOTAL(109,Table52[Total Saturday]) -> 7 | N9: =SUBTOTAL(109,Table52[Wkd Earning]) -> 1388100 | O9: =SUBTOTAL(109,Table52[Wkd Ovt Amt]) -> 0 | P9: =SUBTOTAL(109,Table52[Sat Ovt Amt]) -> 12393.75 | Q9: =SUBTOTAL(109,Table52[Sun Ovt Amt]) -> 0 | R9: =SUBTOTAL(109,Table52[PH Amt]) -> 16525 | S9: =SUBTOTAL(109,Table52[Night Amt]) -> 0 | T9: =SUBTOTAL(109,Table52[Meal Allowance]) -> 73500 | U9: =SUBTOTAL(109,Table52[Transport]) -> 0 | V9: =SUBTOTAL(109,Table52[Total Earnings]) -> 1490518.8 | W9: =SUBTOTAL(109,Table52[WHT]) -> 74525.93 | X9: =SUBTOTAL(109,Table52[Gross Amount]) -> 1490518.8 | Y9: =SUBTOTAL(109,Table52[Amount Payable]) -> 1415992.8

Sheet DLE BANK SCHD
A1: Employee Bank Details
A2: Contractor Code | B2: Contractor Name | C2: Bank | D2: Account No | E2: Sort Code | F2: NET Salary
A3: C0129 | B3: KALU AGWU OKWARA | C3: Fidelity Bank Plc | D3: 4020099243 | E3: 070150003 | F3: =_xlfn.XLOOKUP(Table13[[#This Row],[Contractor Code]],DLE!A:A,DLE!AB:AB) -> 353385.75
A4: C0293 | B4: OLANIYAN OLAKUNLE | C4: Guaranty Trust Bank Plc | D4: 0128756772 | E4: 058152052 | F4: =_xlfn.XLOOKUP(Table13[[#This Row],[Contractor Code]],DLE!A:A,DLE!AB:AB) -> 451635.94
A5: C0585 | B5: FEMI BELLO | C5: Access Bank Plc | D5: 0000214630 | E5: 044150149 | F5: =_xlfn.XLOOKUP(Table13[[#This Row],[Contractor Code]],DLE!A:A,DLE!AB:AB) -> 429352.5
A6: C0695 | B6: AWOYEMI JULIUS | C6: Fidelity Bank Plc | D6: 4020105283 | E6: 070150003 | F6: =_xlfn.XLOOKUP(Table13[[#This Row],[Contractor Code]],DLE!A:A,DLE!AB:AB) -> 402396.25
A7: C0974 | B7: ETUERI STEPHEN | C7: Zenith Bank Plc | D7: 2082484750 | E7: 057150013 | F7: =_xlfn.XLOOKUP(Table13[[#This Row],[Contractor Code]],DLE!A:A,DLE!AB:AB) -> 404236.87
A8: C1001 | B8: GBADAMOSI JIMOH | C8: Guaranty Trust Bank Plc | D8: 0606367290 | E8: 058152052 | F8: =_xlfn.XLOOKUP(Table13[[#This Row],[Contractor Code]],DLE!A:A,DLE!AB:AB) -> 436732.81
A9: C1035 | B9: EJEH DONATUS | C9: Guaranty Trust Bank Plc | D9: 0147788781 | E9: 058152052 | F9: =_xlfn.XLOOKUP(Table13[[#This Row],[Contractor Code]],DLE!A:A,DLE!AB:AB) -> 346491.72
A10: C1065 | B10: OGHENERIE VINCENT | C10: Fidelity Bank Plc | D10: 6050577180 | E10: 070150003 | F10: =_xlfn.XLOOKUP(Table13[[#This Row],[Contractor Code]],DLE!A:A,DLE!AB:AB) -> 383730.54
A11: C1078 | B11: LUKPATA MATHIAS | C11: Fidelity Bank Plc | D11: 6160593533 | E11: 070150003 | F11: =_xlfn.XLOOKUP(Table13[[#This Row],[Contractor Code]],DLE!A:A,DLE!AB:AB) -> 356695.31
A12: C1096 | B12: ADEDOYIN DUROJAYE | C12: Guaranty Trust Bank Plc | D12: 0014252324 | E12: 058152052 | F12: =_xlfn.XLOOKUP(Table13[[#This Row],[Contractor Code]],DLE!A:A,DLE!AB:AB) -> 389737.5
A13: C1144 | B13: OGWUA CHRIS | C13: Fidelity Bank Plc | D13: 6231398469 | E13: 070150003 | F13: =_xlfn.XLOOKUP(Table13[[#This Row],[Contractor Code]],DLE!A:A,DLE!AB:AB) -> 40042.5
A14: C1162 | B14: ADEKOYA ADEWALE | C14: Polaris Bank | D14: 3011580494 | E14: 076151006 | F14: =_xlfn.XLOOKUP(Table13[[#This Row],[Contractor Code]],DLE!A:A,DLE!AB:AB) -> 591959.84
A15: C1220 | B15: NWODO DANIEL | C15: Fidelity Bank Plc | D15: 6017773770 | F15: =_xlfn.XLOOKUP(Table13[[#This Row],[Contractor Code]],DLE!A:A,DLE!AB:AB) -> 332714.95
A16: C1229 | B16: OLAWALE SHITTU | C16: Guaranty Trust Bank Plc | D16: 0664256978 | E16: 058152052 | F16: =_xlfn.XLOOKUP(Table13[[#This Row],[Contractor Code]],DLE!A:A,DLE!AB:AB) -> 56038.12
A17: C1491 | B17: VINCENT NNAMDI | C17: Fidelity Bank Plc | D17: 4020099542 | E17: 070150003 | F17: =_xlfn.XLOOKUP(Table13[[#This Row],[Contractor Code]],DLE!A:A,DLE!AB:AB) -> 294005.71
A18: C1533 | B18: OKEKE VINCENT | C18: Stanbic IBTC Bank Plc | D18: 0033804939 | E18: 221150014 | F18: =_xlfn.XLOOKUP(Table13[[#This Row],[Contractor Code]],DLE!A:A,DLE!AB:AB) -> 420755
A19: C1544 | B19: ADENIYI JOSEPH | C19: United Bank for Africa Plc | D19: 2188685084 | E19: 033150011 | F19: =_xlfn.XLOOKUP(Table13[[#This Row],[Contractor Code]],DLE!A:A,DLE!AB:AB) -> 234084.75
A20: C1607 | B20: OJIKA CHUKWUDUMEBI | C20: Zenith Bank Plc | D20: 2088853873 | E20: 057150013 | F20: =_xlfn.XLOOKUP(Table13[[#This Row],[Contractor Code]],DLE!A:A,DLE!AB:AB) -> 344392.81
A21: C1612 | B21: MBAMARA RICHARD | C21: Fidelity Bank Plc | D21: 6237537987 | E21: 070150003 | F21: =_xlfn.XLOOKUP(Table13[[#This Row],[Contractor Code]],DLE!A:A,DLE!AB:AB) -> 397670
A22: C1686 | B22: FRED MICAH | C22: Zenith Bank Plc | D22: 2003154957 | E22: 057150013 | F22: =_xlfn.XLOOKUP(Table13[[#This Row],[Contractor Code]],DLE!A:A,DLE!AB:AB) -> 71392.5
A23: C1705 | B23: ROTIMI MATTHEW | C23: Guaranty Trust Bank Plc | D23: 0212808307 | E23: 058152052 | F23: =_xlfn.XLOOKUP(Table13[[#This Row],[Contractor Code]],DLE!A:A,DLE!AB:AB) -> 311837.5
A24: C1720 | B24: RAYMOND ADANOU | C24: Fidelity Bank Plc | D24: 6050576451 | E24: 070150003 | F24: =_xlfn.XLOOKUP(Table13[[#This Row],[Contractor Code]],DLE!A:A,DLE!AB:AB) -> 346165.16
A25: C1728 | B25: IBRAHIM MOHAMMED | C25: Guaranty Trust Bank Plc | D25: 0026316672 | E25: 058152052 | F25: =_xlfn.XLOOKUP(Table13[[#This Row],[Contractor Code]],DLE!A:A,DLE!AB:AB) -> 328937.5
A26: C1736 | B26: JEROME MICHAEL | C26: Skye Bank | D26: 1762982279 | E26: 076151006 | F26: =_xlfn.XLOOKUP(Table13[[#This Row],[Contractor Code]],DLE!A:A,DLE!AB:AB) -> 405608.44
A27: C1771 | B27: BADEJO KEHINDE | C27: Fidelity Bank Plc | D27: 6018734020 | E27: 070150003 | F27: =_xlfn.XLOOKUP(Table13[[#This Row],[Contractor Code]],DLE!A:A,DLE!AB:AB) -> 362888.12
... A78: C2154 | B78: BANKOLE SOLOMON | C78: Zenith Bank Plc | D78: 2284108306 | E78: 057150013 | F78: =_xlfn.XLOOKUP(Table13[[#This Row],[Contractor Code]],DLE!A:A,DLE!AB:AB) -> 375362.81
A79: C2171 | B79: AZEMOBO LUCKY | C79: First Bank of Nigeria Limited | D79: 3042849785 | F79: =_xlfn.XLOOKUP(Table13[[#This Row],[Contractor Code]],DLE!A:A,DLE!AB:AB) -> 290272.5
A80: C2193 | B80: EMEH DAVID NWACHUKWU | C80: First Bank of Nigeria Limited | D80: 3057402544 | E80: 011151003 | F80: =_xlfn.XLOOKUP(Table13[[#This Row],[Contractor Code]],DLE!A:A,DLE!AB:AB) -> 311288.29
A81: C2220 | B81: UGBEKILE ABEL | C81: Zenith Bank Plc | D81: 2119101245 | E81: 057150013 | F81: =_xlfn.XLOOKUP(Table13[[#This Row],[Contractor Code]],DLE!A:A,DLE!AB:AB) -> 291130.47
A82: C2221 | B82: YUNUS KAMORUDEEN | C82: Stanbic IBTC Bank Plc | D82: 0040479212 | E82: 221150014 | F82: =_xlfn.XLOOKUP(Table13[[#This Row],[Contractor Code]],DLE!A:A,DLE!AB:AB) -> 253457.04
A83: C2222 | B83: EZEAGU ANTHONY | C83: Access Bank Plc | D83: 1144340412 | E83: 044150149 | F83: =_xlfn.XLOOKUP(Table13[[#This Row],[Contractor Code]],DLE!A:A,DLE!AB:AB) -> 253457.04
A84: C2224 | B84: AGBATA CHRISTIAN | C84: United Bank for Africa Plc | D84: 2057877770 | E84: 033150011 | F84: =_xlfn.XLOOKUP(Table13[[#This Row],[Contractor Code]],DLE!A:A,DLE!AB:AB) -> 253457.04
A85: C2225 | B85: DANIEL ABEL | C85: Guaranty Trust Bank Plc | D85: 0019229341 | E85: 058152052 | F85: =_xlfn.XLOOKUP(Table13[[#This Row],[Contractor Code]],DLE!A:A,DLE!AB:AB) -> 285479.46
A86: C2236 | B86: IWUAGWU KELVIN NDUBUISI | C86: Fidelity Bank Plc | D86: 4020101058 | E86: 070150003 | F86: =_xlfn.XLOOKUP(Table13[[#This Row],[Contractor Code]],DLE!A:A,DLE!AB:AB) -> 335987.69
A87: C2290 | B87: ADEBAYO OLUWATOSIN | C87: Keystone Bank Limited | D87: 6023280856 | F87: =_xlfn.XLOOKUP(Table13[[#This Row],[Contractor Code]],DLE!A:A,DLE!AB:AB) -> 326941.91
A88: C2291 | B88: UMA NGELE OKEY | C88: Fidelity Bank Plc | D88: 4020103980 | E88: 070150003 | F88: =_xlfn.XLOOKUP(Table13[[#This Row],[Contractor Code]],DLE!A:A,DLE!AB:AB) -> 228705.37
A89: C2300 | B89: TAIWO GABRIEL PONMILE | C89: First Bank of Nigeria Limited | D89: 3015733305 | F89: =_xlfn.XLOOKUP(Table13[[#This Row],[Contractor Code]],DLE!A:A,DLE!AB:AB) -> 378699.69
A90: C2319 | B90: TORTI NDUBUISI | C90: Zenith Bank Plc | D90: 4211388821 | E90: 057150013 | F90: =_xlfn.XLOOKUP(Table13[[#This Row],[Contractor Code]],DLE!A:A,DLE!AB:AB) -> 377806.69
...

Sheet DLPC.BANK.SCHD
A1: Employee Bank Details
A2: Contractor Code | B2: Contractor Name | C2: Bank | D2: Account No | E2: Sort Code | F2: NET Salary | G2: Location
A3: C2394 | B3: HAMMED IDOWU | C3: Guaranty Trust Bank Plc | D3: 0729570216 | E3: 058152052 | F3: =_xlfn.XLOOKUP(Table146[[#This Row],[Contractor Code]],Table52[Contractor Code],Table52[Amount Payable]) -> 203448.44 | G3: AGEGE
A4: C2396 | B4: AKINDELE MUSBAU | C4: Fidelity Bank Plc | D4: 5330178152 | E4: 070150003 | F4: =_xlfn.XLOOKUP(Table146[[#This Row],[Contractor Code]],Table52[Contractor Code],Table52[Amount Payable]) -> 203448.44 | G4: AGEGE
A5: C2408 | B5: ANTHONY LAWRENCE | C5: Guaranty Trust Bank Plc | D5: 0742476502 | E5: 058152052 | F5: =_xlfn.XLOOKUP(Table146[[#This Row],[Contractor Code]],Table52[Contractor Code],Table52[Amount Payable]) -> 213631.25 | G5: AGEGE
A6: C2443 | B6: GANIYU ADEBIYI | C6: Guaranty Trust Bank Plc | D6: 0254241197 | E6: 058152052 | F6: =_xlfn.XLOOKUP(Table146[[#This Row],[Contractor Code]],Table52[Contractor Code],Table52[Amount Payable]) -> 203448.44 | G6: AGEGE
A7: C2506 | B7: ONOJA MICHAEL | C7: Guaranty Trust Bank Plc | D7: 0797313568 | E7: 058152052 | F7: =_xlfn.XLOOKUP(Table146[[#This Row],[Contractor Code]],Table52[Contractor Code],Table52[Amount Payable]) -> 203448.44 | G7: AGEGE
A8: C2512 | B8: OVAT SUNDAY | C8: Zenith Bank Plc | D8: 4243185836 | E8: 057150013 | F8: =_xlfn.XLOOKUP(Table146[[#This Row],[Contractor Code]],Table52[Contractor Code],Table52[Amount Payable]) -> 185119.37 | G8: AGEGE
A9: C2522 | B9: RASAK JAMIU | C9: Guaranty Trust Bank Plc | D9: 0743000458 | E9: 058152052 | F9: =_xlfn.XLOOKUP(Table146[[#This Row],[Contractor Code]],Table52[Contractor Code],Table52[Amount Payable]) -> 203448.44 | G9: AGEGE
A10: =SUBTOTAL(103,Table146[Contractor Code]) -> 7 | F10: =SUBTOTAL(109,Table146[NET Salary]) -> 1415992.8
