Workbook

Sheet SUMMARY
A1: AUGUST 2026 DAYRATE PAYMENT SCHEDULE
A3: COMPANY | B3: HEADCOUNT | C3: GROSS PAY | D3: NET PAY
A4: DLE | B4: =Table4[[#Totals],[Emp. Code]] -> 181 | C4: =Table4[[#Totals],[Gross Salary]] -> 68406170 | D4: =Table4[[#Totals],[Net Pay]] -> 64985862
A5: DLPC | B5: =Table52[[#Totals],[Emp. Code]] -> 7 | C5: =Table52[[#Totals],[Gross Salary]] -> 1656987.5 | D5: =Table52[[#Totals],[Net Pay]] -> 1574138.1
A6: Total | B6: =SUBTOTAL(109,Table7[HEADCOUNT]) -> 188 | C6: =SUBTOTAL(109,Table7[GROSS PAY]) -> 70063158 | D6: =SUBTOTAL(109,Table7[NET PAY]) -> 66560000

Sheet DLE
A1: Emp. Code | B1: First Name | C1: Last Name | D1: Job Title | E1: Location | F1: Daily Rate | G1: AGE | H1: Gender | I1: Total Weekday | J1: Weekday OVT | K1: Total Saturday | L1: Total Sunday | M1: Night Worked | N1: Wkd Earning | O1: Wkd Ovt Amt | P1: Sat Ovt Amt | Q1: Sun Ovt Amt | R1: Night Amt | S1: Meal Allowance | T1: Transport | U1: Site Allowance | V1: TCM Meal | W1: TCM TRANSPORT | X1: Arrears | Y1: Total Earnings | Z1: WHT | AA1: Gross Salary | AB1: Net Pay
A2: C1065 | B2: VINCENT | C2: OGHENERIE | D2: FITTER 1 | E2: IDI - IDI_ORO | F2: 14050 | G2: 63 | H2: M | I2: 22 | J2: 13 | K2: 0 | L2: 0 | M2: 0 | N2: =Table4[[#This Row],[Total Weekday]]*Table4[[#This Row],[Daily Rate]] -> 309100 | O2: =Table4[[#This Row],[Daily Rate]]/8*1.5*Table4[[#This Row],[Weekday OVT]] -> 34246.875 | P2: =Table4[[#This Row],[Daily Rate]]/8*(1.5*Table4[[#This Row],[Total Saturday]]) -> 0 | Q2: =Table4[[#This Row],[Daily Rate]]/8*(2*Table4[[#This Row],[Total Sunday]]) -> 0 | R2: =2500*Table4[[#This Row],[Night Worked]] -> 0 | S2: =500*Table4[[#This Row],[Total Weekday]] -> 11000 | Y2: =SUM(Table4[[#This Row],[Wkd Earning]:[Arrears]]) -> 354346.88 | Z2: =0.05*Table4[[#This Row],[Total Earnings]] -> 17717.344 | AA2: =Table4[[#This Row],[Total Earnings]] -> 354346.88 | AB2: =Table4[[#This Row],[Gross Salary]]-Table4[[#This Row],[WHT]] -> 336629.53
A3: C1888 | B3: OLATUNJI | C3: YEKINI | D3: 6GR (SMAW & GTAW) | E3: IDI - IDI_ORO | F3: 16700 | G3: 57 | H3: M | I3: 22 | J3: 10 | K3: 0 | L3: 0 | M3: 0 | N3: =Table4[[#This Row],[Total Weekday]]*Table4[[#This Row],[Daily Rate]] -> 367400 | O3: =Table4[[#This Row],[Daily Rate]]/8*1.5*Table4[[#This Row],[Weekday OVT]] -> 31312.5 | P3: =Table4[[#This Row],[Daily Rate]]/8*(1.5*Table4[[#This Row],[Total Saturday]]) -> 0 | Q3: =Table4[[#This Row],[Daily Rate]]/8*(2*Table4[[#This Row],[Total Sunday]]) -> 0 | R3: =2500*Table4[[#This Row],[Night Worked]] -> 0 | S3: =500*Table4[[#This Row],[Total Weekday]] -> 11000 | Y3: =SUM(Table4[[#This Row],[Wkd Earning]:[Arrears]]) -> 409712.5 | Z3: =0.05*Table4[[#This Row],[Total Earnings]] -> 20485.625 | AA3: =Table4[[#This Row],[Total Earnings]] -> 409712.5 | AB3: =Table4[[#This Row],[Gross Salary]]-Table4[[#This Row],[WHT]] -> 389226.88
A4: C2513 | B4: OLAYIWOLA | C4: OWOLABI | D4: FITTER | E4: IDI - IDI_ORO | F4: 14050 | G4: 62 | H4: M | I4: 22 | J4: 14 | K4: 0 | L4: 0 | M4: 0 | N4: =Table4[[#This Row],[Total Weekday]]*Table4[[#This Row],[Daily Rate]] -> 309100 | O4: =Table4[[#This Row],[Daily Rate]]/8*1.5*Table4[[#This Row],[Weekday OVT]] -> 36881.25 | P4: =Table4[[#This Row],[Daily Rate]]/8*(1.5*Table4[[#This Row],[Total Saturday]]) -> 0 | Q4: =Table4[[#This Row],[Daily Rate]]/8*(2*Table4[[#This Row],[Total Sunday]]) -> 0 | R4: =2500*Table4[[#This Row],[Night Worked]] -> 0 | S4: =500*Table4[[#This Row],[Total Weekday]] -> 11000 | Y4: =SUM(Table4[[#This Row],[Wkd Earning]:[Arrears]]) -> 356981.25 | Z4: =0.05*Table4[[#This Row],[Total Earnings]] -> 17849.062 | AA4: =Table4[[#This Row],[Total Earnings]] -> 356981.25 | AB4: =Table4[[#This Row],[Gross Salary]]-Table4[[#This Row],[WHT]] -> 339132.19
A5: C0129 | B5: AGWU | C5: KALU | D5: GRINDER/PWHT ASSISTANT | E5: IDI - IDI_ORO | F5: 13050 | G5: 64 | H5: M | I5: 22 | J5: 12 | K5: 0 | L5: 0 | M5: 0 | N5: =Table4[[#This Row],[Total Weekday]]*Table4[[#This Row],[Daily Rate]] -> 287100 | O5: =Table4[[#This Row],[Daily Rate]]/8*1.5*Table4[[#This Row],[Weekday OVT]] -> 29362.5 | P5: =Table4[[#This Row],[Daily Rate]]/8*(1.5*Table4[[#This Row],[Total Saturday]]) -> 0 | Q5: =Table4[[#This Row],[Daily Rate]]/8*(2*Table4[[#This Row],[Total Sunday]]) -> 0 | R5: =2500*Table4[[#This Row],[Night Worked]] -> 0 | S5: =500*Table4[[#This Row],[Total Weekday]] -> 11000 | Y5: =SUM(Table4[[#This Row],[Wkd Earning]:[Arrears]]) -> 327462.5 | Z5: =0.05*Table4[[#This Row],[Total Earnings]] -> 16373.125 | AA5: =Table4[[#This Row],[Total Earnings]] -> 327462.5 | AB5: =Table4[[#This Row],[Gross Salary]]-Table4[[#This Row],[WHT]] -> 311089.38
A6: C0293 | B6: OLAKUNLE | C6: OLANIYAN | D6: ELECTRICIAN | E6: IDI - IDI_ORO | F6: 10250 | G6: 57 | H6: M | I6: 27 | J6: 43 | K6: 35 | L6: 10 | M6: 8 | N6: =Table4[[#This Row],[Total Weekday]]*Table4[[#This Row],[Daily Rate]] -> 276750 | O6: =Table4[[#This Row],[Daily Rate]]/8*1.5*Table4[[#This Row],[Weekday OVT]] -> 82640.625 | P6: =Table4[[#This Row],[Daily Rate]]/8*(1.5*Table4[[#This Row],[Total Saturday]]) -> 67265.625 | Q6: =Table4[[#This Row],[Daily Rate]]/8*(2*Table4[[#This Row],[Total Sunday]]) -> 25625 | R6: =2500*Table4[[#This Row],[Night Worked]] -> 20000 | S6: =500*Table4[[#This Row],[Total Weekday]] -> 13500 | Y6: =SUM(Table4[[#This Row],[Wkd Earning]:[Arrears]]) -> 485781.25 | Z6: =0.05*Table4[[#This Row],[Total Earnings]] -> 24289.062 | AA6: =Table4[[#This Row],[Total Earnings]] -> 485781.25 | AB6: =Table4[[#This Row],[Gross Salary]]-Table4[[#This Row],[WHT]] -> 461492.19
A7: C0974 | B7: STEPHEN | C7: ETUERI | D7: MACHINE SHOP SUPRITENDENT | E7: IDI - IDI_ORO | F7: 17850 | G7: 78 | H7: M | I7: 22 | J7: 0 | K7: 0 | L7: 0 | M7: 0 | N7: =Table4[[#This Row],[Total Weekday]]*Table4[[#This Row],[Daily Rate]] -> 392700 | O7: =Table4[[#This Row],[Daily Rate]]/8*1.5*Table4[[#This Row],[Weekday OVT]] -> 0 | P7: =Table4[[#This Row],[Daily Rate]]/8*(1.5*Table4[[#This Row],[Total Saturday]]) -> 0 | Q7: =Table4[[#This Row],[Daily Rate]]/8*(2*Table4[[#This Row],[Total Sunday]]) -> 0 | R7: =2500*Table4[[#This Row],[Night Worked]] -> 0 | S7: =500*Table4[[#This Row],[Total Weekday]] -> 11000 | Y7: =SUM(Table4[[#This Row],[Wkd Earning]:[Arrears]]) -> 403700 | Z7: =0.05*Table4[[#This Row],[Total Earnings]] -> 20185 | AA7: =Table4[[#This Row],[Total Earnings]] -> 403700 | AB7: =Table4[[#This Row],[Gross Salary]]-Table4[[#This Row],[WHT]] -> 383515
A8: C1035 | B8: DONATUS | C8: EJEH | D8: RIGGER | E8: IDI - IDI_ORO | F8: 13150 | G8: 52 | H8: M | I8: 22 | J8: 10 | K8: 0 | L8: 0 | M8: 0 | N8: =Table4[[#This Row],[Total Weekday]]*Table4[[#This Row],[Daily Rate]] -> 289300 | O8: =Table4[[#This Row],[Daily Rate]]/8*1.5*Table4[[#This Row],[Weekday OVT]] -> 24656.25 | P8: =Table4[[#This Row],[Daily Rate]]/8*(1.5*Table4[[#This Row],[Total Saturday]]) -> 0 | Q8: =Table4[[#This Row],[Daily Rate]]/8*(2*Table4[[#This Row],[Total Sunday]]) -> 0 | R8: =2500*Table4[[#This Row],[Night Worked]] -> 0 | S8: =500*Table4[[#This Row],[Total Weekday]] -> 11000 | Y8: =SUM(Table4[[#This Row],[Wkd Earning]:[Arrears]]) -> 324956.25 | Z8: =0.05*Table4[[#This Row],[Total Earnings]] -> 16247.812 | AA8: =Table4[[#This Row],[Total Earnings]] -> 324956.25 | AB8: =Table4[[#This Row],[Gross Salary]]-Table4[[#This Row],[WHT]] -> 308708.44
A9: C1162 | B9: ADEWALE | C9: ADEKOYA | D9: 6GR (SMAW & GTAW) | E9: IDI - IDI_ORO | F9: 23500 | G9: 55 | H9: M | I9: 25 | J9: 15 | K9: 6 | L9: 0 | M9: 0 | N9: =Table4[[#This Row],[Total Weekday]]*Table4[[#This Row],[Daily Rate]] -> 587500 | O9: =Table4[[#This Row],[Daily Rate]]/8*1.5*Table4[[#This Row],[Weekday OVT]] -> 66093.75 | P9: =Table4[[#This Row],[Daily Rate]]/8*(1.5*Table4[[#This Row],[Total Saturday]]) -> 26437.5 | Q9: =Table4[[#This Row],[Daily Rate]]/8*(2*Table4[[#This Row],[Total Sunday]]) -> 0 | R9: =2500*Table4[[#This Row],[Night Worked]] -> 0 | S9: =500*Table4[[#This Row],[Total Weekday]] -> 12500 | T9: 12000 | Y9: =SUM(Table4[[#This Row],[Wkd Earning]:[Arrears]]) -> 704531.25 | Z9: =0.05*Table4[[#This Row],[Total Earnings]] -> 35226.562 | AA9: =Table4[[#This Row],[Total Earnings]] -> 704531.25 | AB9: =Table4[[#This Row],[Gross Salary]]-Table4[[#This Row],[WHT]] -> 669304.69
A10: C1491 | B10: NNAMDI | C10: VINCENT | D10: GRINDER | E10: IDI - IDI_ORO | F10: 10250 | G10: 46 | H10: M | I10: 22 | J10: 10 | K10: 0 | L10: 0 | M10: 0 | N10: =Table4[[#This Row],[Total Weekday]]*Table4[[#This Row],[Daily Rate]] -> 225500 | O10: =Table4[[#This Row],[Daily Rate]]/8*1.5*Table4[[#This Row],[Weekday OVT]] -> 19218.75 | P10: =Table4[[#This Row],[Daily Rate]]/8*(1.5*Table4[[#This Row],[Total Saturday]]) -> 0 | Q10: =Table4[[#This Row],[Daily Rate]]/8*(2*Table4[[#This Row],[Total Sunday]]) -> 0 | R10: =2500*Table4[[#This Row],[Night Worked]] -> 0 | S10: =500*Table4[[#This Row],[Total Weekday]] -> 11000 | Y10: =SUM(Table4[[#This Row],[Wkd Earning]:[Arrears]]) -> 255718.75 | Z10: =0.05*Table4[[#This Row],[Total Earnings]] -> 12785.938 | AA10: =Table4[[#This Row],[Total Earnings]] -> 255718.75 | AB10: =Table4[[#This Row],[Gross Salary]]-Table4[[#This Row],[WHT]] -> 242932.81
A11: C1705 | B11: MATTHEW | C11: ROTIMI | D11: MECHANIC | E11: IDI - IDI_ORO | F11: 10250 | G11: 47 | H11: M | I11: 29 | J11: 15 | K11: 45 | L11: 20 | M11: 0 | N11: =Table4[[#This Row],[Total Weekday]]*Table4[[#This Row],[Daily Rate]] -> 297250 | O11: =Table4[[#This Row],[Daily Rate]]/8*1.5*Table4[[#This Row],[Weekday OVT]] -> 28828.125 | P11: =Table4[[#This Row],[Daily Rate]]/8*(1.5*Table4[[#This Row],[Total Saturday]]) -> 86484.375 | Q11: =Table4[[#This Row],[Daily Rate]]/8*(2*Table4[[#This Row],[Total Sunday]]) -> 51250 | R11: =2500*Table4[[#This Row],[Night Worked]] -> 0 | S11: =500*Table4[[#This Row],[Total Weekday]] -> 14500 | Y11: =SUM(Table4[[#This Row],[Wkd Earning]:[Arrears]]) -> 478312.5 | Z11: =0.05*Table4[[#This Row],[Total Earnings]] -> 23915.625 | AA11: =Table4[[#This Row],[Total Earnings]] -> 478312.5 | AB11: =Table4[[#This Row],[Gross Salary]]-Table4[[#This Row],[WHT]] -> 454396.88
A12: C1728 | B12: MOHAMMED | C12: IBRAHIM | D12: 6GR (SMAW & GTAW) | E12: IDI - IDI_ORO | F12: 23500 | G12: 38 | H12: M | I12: 25 | J12: 10 | K12: 11 | L12: 0 | M12: 0 | N12: =Table4[[#This Row],[Total Weekday]]*Table4[[#This Row],[Daily Rate]] -> 587500 | O12: =Table4[[#This Row],[Daily Rate]]/8*1.5*Table4[[#This Row],[Weekday OVT]] -> 44062.5 | P12: =Table4[[#This Row],[Daily Rate]]/8*(1.5*Table4[[#This Row],[Total Saturday]]) -> 48468.75 | Q12: =Table4[[#This Row],[Daily Rate]]/8*(2*Table4[[#This Row],[Total Sunday]]) -> 0 | R12: =2500*Table4[[#This Row],[Night Worked]] -> 0 | S12: =500*Table4[[#This Row],[Total Weekday]] -> 12500 | Y12: =SUM(Table4[[#This Row],[Wkd Earning]:[Arrears]]) -> 692531.25 | Z12: =0.05*Table4[[#This Row],[Total Earnings]] -> 34626.562 | AA12: =Table4[[#This Row],[Total Earnings]] -> 692531.25 | AB12: =Table4[[#This Row],[Gross Salary]]-Table4[[#This Row],[WHT]] -> 657904.69
A13: C1779 | B13: KENNEDY | C13: EBUNO | D13: SMAW&GTAW (CS) WELDER | E13: IDI - IDI_ORO | F13: 23500 | G13: 62 | H13: M | I13: 24 | J13: 17 | K13: 0 | L13: 0 | M13: 0 | N13: =Table4[[#This Row],[Total Weekday]]*Table4[[#This Row],[Daily Rate]] -> 564000 | O13: =Table4[[#This Row],[Daily Rate]]/8*1.5*Table4[[#This Row],[Weekday OVT]] -> 74906.25 | P13: =Table4[[#This Row],[Daily Rate]]/8*(1.5*Table4[[#This Row],[Total Saturday]]) -> 0 | Q13: =Table4[[#This Row],[Daily Rate]]/8*(2*Table4[[#This Row],[Total Sunday]]) -> 0 | R13: =2500*Table4[[#This Row],[Night Worked]] -> 0 | S13: =500*Table4[[#This Row],[Total Weekday]] -> 12000 | Y13: =SUM(Table4[[#This Row],[Wkd Earning]:[Arrears]]) -> 650906.25 | Z13: =0.05*Table4[[#This Row],[Total Earnings]] -> 32545.312 | AA13: =Table4[[#This Row],[Total Earnings]] -> 650906.25 | AB13: =Table4[[#This Row],[Gross Salary]]-Table4[[#This Row],[WHT]] -> 618360.94
A14: C1788 | B14: JONAH | C14: SAMUEL | D14: FITTER | E14: IDI - IDI_ORO | F14: 14050 | G14: 49 | H14: M | I14: 22 | J14: 6 | K14: 0 | L14: 0 | M14: 0 | N14: =Table4[[#This Row],[Total Weekday]]*Table4[[#This Row],[Daily Rate]] -> 309100 | O14: =Table4[[#This Row],[Daily Rate]]/8*1.5*Table4[[#This Row],[Weekday OVT]] -> 15806.25 | P14: =Table4[[#This Row],[Daily Rate]]/8*(1.5*Table4[[#This Row],[Total Saturday]]) -> 0 | Q14: =Table4[[#This Row],[Daily Rate]]/8*(2*Table4[[#This Row],[Total Sunday]]) -> 0 | R14: =2500*Table4[[#This Row],[Night Worked]] -> 0 | S14: =500*Table4[[#This Row],[Total Weekday]] -> 11000 | Y14: =SUM(Table4[[#This Row],[Wkd Earning]:[Arrears]]) -> 335906.25 | Z14: =0.05*Table4[[#This Row],[Total Earnings]] -> 16795.312 | AA14: =Table4[[#This Row],[Total Earnings]] -> 335906.25 | AB14: =Table4[[#This Row],[Gross Salary]]-Table4[[#This Row],[WHT]] -> 319110.94
A15: C1820 | B15: SUNDAY | C15: OKORO | D15: FITTER | E15: IDI - IDI_ORO | F15: 14050 | G15: 56 | H15: M | I15: 22 | J15: 13 | K15: 0 | L15: 0 | M15: 0 | N15: =Table4[[#This Row],[Total Weekday]]*Table4[[#This Row],[Daily Rate]] -> 309100 | O15: =Table4[[#This Row],[Daily Rate]]/8*1.5*Table4[[#This Row],[Weekday OVT]] -> 34246.875 | P15: =Table4[[#This Row],[Daily Rate]]/8*(1.5*Table4[[#This Row],[Total Saturday]]) -> 0 | Q15: =Table4[[#This Row],[Daily Rate]]/8*(2*Table4[[#This Row],[Total Sunday]]) -> 0 | R15: =2500*Table4[[#This Row],[Night Worked]] -> 0 | S15: =500*Table4[[#This Row],[Total Weekday]] -> 11000 | Y15: =SUM(Table4[[#This Row],[Wkd Earning]:[Arrears]]) -> 354346.88 | Z15: =0.05*Table4[[#This Row],[Total Earnings]] -> 17717.344 | AA15: =Table4[[#This Row],[Total Earnings]] -> 354346.88 | AB15: =Table4[[#This Row],[Gross Salary]]-Table4[[#This Row],[WHT]] -> 336629.53
A16: C1823 | B16: MATTHEW | C16: EGBUJOR | D16: GRINDER | E16: IDI - IDI_ORO | F16: 10250 | G16: 61 | H16: M | I16: 22 | J16: 15 | K16: 0 | L16: 0 | M16: 0 | N16: =Table4[[#This Row],[Total Weekday]]*Table4[[#This Row],[Daily Rate]] -> 225500 | O16: =Table4[[#This Row],[Daily Rate]]/8*1.5*Table4[[#This Row],[Weekday OVT]] -> 28828.125 | P16: =Table4[[#This Row],[Daily Rate]]/8*(1.5*Table4[[#This Row],[Total Saturday]]) -> 0 | Q16: =Table4[[#This Row],[Daily Rate]]/8*(2*Table4[[#This Row],[Total Sunday]]) -> 0 | R16: =2500*Table4[[#This Row],[Night Worked]] -> 0 | S16: =500*Table4[[#This Row],[Total Weekday]] -> 11000 | Y16: =SUM(Table4[[#This Row],[Wkd Earning]:[Arrears]]) -> 265328.12 | Z16: =0.05*Table4[[#This Row],[Total Earnings]] -> 13266.406 | AA16: =Table4[[#This Row],[Total Earnings]] -> 265328.12 | AB16: =Table4[[#This Row],[Gross Salary]]-Table4[[#This Row],[WHT]] -> 252061.72
A17: C1824 | B17: ALPHONSUS | C17: ADAOWO | D17: FITTER | E17: IDI - IDI_ORO | F17: 14050 | G17: 45 | H17: M | I17: 22 | J17: 4 | K17: 0 | L17: 0 | M17: 0 | N17: =Table4[[#This Row],[Total Weekday]]*Table4[[#This Row],[Daily Rate]] -> 309100 | O17: =Table4[[#This Row],[Daily Rate]]/8*1.5*Table4[[#This Row],[Weekday OVT]] -> 10537.5 | P17: =Table4[[#This Row],[Daily Rate]]/8*(1.5*Table4[[#This Row],[Total Saturday]]) -> 0 | Q17: =Table4[[#This Row],[Daily Rate]]/8*(2*Table4[[#This Row],[Total Sunday]]) -> 0 | R17: =2500*Table4[[#This Row],[Night Worked]] -> 0 | S17: =500*Table4[[#This Row],[Total Weekday]] -> 11000 | Y17: =SUM(Table4[[#This Row],[Wkd Earning]:[Arrears]]) -> 330637.5 | Z17: =0.05*Table4[[#This Row],[Total Earnings]] -> 16531.875 | AA17: =Table4[[#This Row],[Total Earnings]] -> 330637.5 | AB17: =Table4[[#This Row],[Gross Salary]]-Table4[[#This Row],[WHT]] -> 314105.62
A18: C1840 | B18: FRIDAY | C18: ISINGUZO | D18: GRINDER | E18: IDI - IDI_ORO | F18: 10250 | G18: 59 | H18: M | I18: 22 | J18: 13 | K18: 0 | L18: 0 | M18: 0 | N18: =Table4[[#This Row],[Total Weekday]]*Table4[[#This Row],[Daily Rate]] -> 225500 | O18: =Table4[[#This Row],[Daily Rate]]/8*1.5*Table4[[#This Row],[Weekday OVT]] -> 24984.375 | P18: =Table4[[#This Row],[Daily Rate]]/8*(1.5*Table4[[#This Row],[Total Saturday]]) -> 0 | Q18: =Table4[[#This Row],[Daily Rate]]/8*(2*Table4[[#This Row],[Total Sunday]]) -> 0 | R18: =2500*Table4[[#This Row],[Night Worked]] -> 0 | S18: =500*Table4[[#This Row],[Total Weekday]] -> 11000 | Y18: =SUM(Table4[[#This Row],[Wkd Earning]:[Arrears]]) -> 261484.38 | Z18: =0.05*Table4[[#This Row],[Total Earnings]] -> 13074.219 | AA18: =Table4[[#This Row],[Total Earnings]] -> 261484.38 | AB18: =Table4[[#This Row],[Gross Salary]]-Table4[[#This Row],[WHT]] -> 248410.16
A19: C1849 | B19: SUCCESS | C19: OKORIE | D19: FACTORY CLEANER | E19: IDI - IDI_ORO | F19: 8600 | G19: 35 | H19: M | I19: 22 | J19: 0 | K19: 0 | L19: 0 | M19: 0 | N19: =Table4[[#This Row],[Total Weekday]]*Table4[[#This Row],[Daily Rate]] -> 189200 | O19: =Table4[[#This Row],[Daily Rate]]/8*1.5*Table4[[#This Row],[Weekday OVT]] -> 0 | P19: =Table4[[#This Row],[Daily Rate]]/8*(1.5*Table4[[#This Row],[Total Saturday]]) -> 0 | Q19: =Table4[[#This Row],[Daily Rate]]/8*(2*Table4[[#This Row],[Total Sunday]]) -> 0 | R19: =2500*Table4[[#This Row],[Night Worked]] -> 0 | S19: =500*Table4[[#This Row],[Total Weekday]] -> 11000 | Y19: =SUM(Table4[[#This Row],[Wkd Earning]:[Arrears]]) -> 200200 | Z19: =0.05*Table4[[#This Row],[Total Earnings]] -> 10010 | AA19: =Table4[[#This Row],[Total Earnings]] -> 200200 | AB19: =Table4[[#This Row],[Gross Salary]]-Table4[[#This Row],[WHT]] -> 190190
A20: C1882 | B20: MOMOH | C20: MOHAMMED | D20: FITTER SUPERVISOR | E20: IDI - IDI_ORO | F20: 17850 | G20: 52 | H20: M | I20: 31 | J20: 0 | K20: 55 | L20: 44 | M20: 0 | N20: =Table4[[#This Row],[Total Weekday]]*Table4[[#This Row],[Daily Rate]] -> 553350 | O20: =Table4[[#This Row],[Daily Rate]]/8*1.5*Table4[[#This Row],[Weekday OVT]] -> 0 | P20: =Table4[[#This Row],[Daily Rate]]/8*(1.5*Table4[[#This Row],[Total Saturday]]) -> 184078.12 | Q20: =Table4[[#This Row],[Daily Rate]]/8*(2*Table4[[#This Row],[Total Sunday]]) -> 196350 | R20: =2500*Table4[[#This Row],[Night Worked]] -> 0 | S20: =500*Table4[[#This Row],[Total Weekday]] -> 15500 | Y20: =SUM(Table4[[#This Row],[Wkd Earning]:[Arrears]]) -> 949278.12 | Z20: =0.05*Table4[[#This Row],[Total Earnings]] -> 47463.906 | AA20: =Table4[[#This Row],[Total Earnings]] -> 949278.12 | AB20: =Table4[[#This Row],[Gross Salary]]-Table4[[#This Row],[WHT]] -> 901814.22
A21: C1920 | B21: AZEEZ | C21: LATEEF | D21: BLASTER/PAINTER | E21: IDI - IDI_ORO | F21: 12750 | G21: 56 | H21: M | I21: 22 | J21: 0 | K21: 0 | L21: 0 | M21: 0 | N21: =Table4[[#This Row],[Total Weekday]]*Table4[[#This Row],[Daily Rate]] -> 280500 | O21: =Table4[[#This Row],[Daily Rate]]/8*1.5*Table4[[#This Row],[Weekday OVT]] -> 0 | P21: =Table4[[#This Row],[Daily Rate]]/8*(1.5*Table4[[#This Row],[Total Saturday]]) -> 0 | Q21: =Table4[[#This Row],[Daily Rate]]/8*(2*Table4[[#This Row],[Total Sunday]]) -> 0 | R21: =2500*Table4[[#This Row],[Night Worked]] -> 0 | S21: =500*Table4[[#This Row],[Total Weekday]] -> 11000 | Y21: =SUM(Table4[[#This Row],[Wkd Earning]:[Arrears]]) -> 291500 | Z21: =0.05*Table4[[#This Row],[Total Earnings]] -> 14575 | AA21: =Table4[[#This Row],[Total Earnings]] -> 291500 | AB21: =Table4[[#This Row],[Gross Salary]]-Table4[[#This Row],[WHT]] -> 276925
... A29: C2404 | B29: MATHEW | C29: AMEH | D29: SCAFFOLDER | E29: IDI - IDI_ORO | F29: 13250 | G29: 41 | H29: M | I29: 22 | J29: 9 | K29: 0 | L29: 0 | M29: 0 | N29: =Table4[[#This Row],[Total Weekday]]*Table4[[#This Row],[Daily Rate]] -> 291500 | O29: =Table4[[#This Row],[Daily Rate]]/8*1.5*Table4[[#This Row],[Weekday OVT]] -> 22359.375 | P29: =Table4[[#This Row],[Daily Rate]]/8*(1.5*Table4[[#This Row],[Total Saturday]]) -> 0 | Q29: =Table4[[#This Row],[Daily Rate]]/8*(2*Table4[[#This Row],[Total Sunday]]) -> 0 | R29: =2500*Table4[[#This Row],[Night Worked]] -> 0 | S29: =500*Table4[[#This Row],[Total Weekday]] -> 11000 | Y29: =SUM(Table4[[#This Row],[Wkd Earning]:[Arrears]]) -> 324859.38 | Z29: =0.05*Table4[[#This Row],[Total Earnings]] -> 16242.969 | AA29: =Table4[[#This Row],[Total Earnings]] -> 324859.38 | AB29: =Table4[[#This Row],[Gross Salary]]-Table4[[#This Row],[WHT]] -> 308616.41
A30: C2421 | B30: OKPE | C30: DANIEL | D30: WELDER MATE | E30: IDI - IDI_ORO | F30: 23500 | G30: 27 | H30: M | I30: 25 | J30: 16 | K30: 6 | L30: 0 | M30: 0 | N30: =Table4[[#This Row],[Total Weekday]]*Table4[[#This Row],[Daily Rate]] -> 587500 | O30: =Table4[[#This Row],[Daily Rate]]/8*1.5*Table4[[#This Row],[Weekday OVT]] -> 70500 | P30: =Table4[[#This Row],[Daily Rate]]/8*(1.5*Table4[[#This Row],[Total Saturday]]) -> 26437.5 | Q30: =Table4[[#This Row],[Daily Rate]]/8*(2*Table4[[#This Row],[Total Sunday]]) -> 0 | R30: =2500*Table4[[#This Row],[Night Worked]] -> 0 | S30: =500*Table4[[#This Row],[Total Weekday]] -> 12500 | T30: 12000 | Y30: =SUM(Table4[[#This Row],[Wkd Earning]:[Arrears]]) -> 708937.5 | Z30: =0.05*Table4[[#This Row],[Total Earnings]] -> 35446.875 | AA30: =Table4[[#This Row],[Total Earnings]] -> 708937.5 | AB30: =Table4[[#This Row],[Gross Salary]]-Table4[[#This Row],[WHT]] -> 673490.62
A31: C2422 | B31: UDEH | C31: DAVID | D31: WELDER MATE | E31: IDI - IDI_ORO | F31: 13550 | G31: 31 | H31: M | I31: 24 | J31: 34 | K31: 17 | L31: 0 | M31: 0 | N31: =Table4[[#This Row],[Total Weekday]]*Table4[[#This Row],[Daily Rate]] -> 325200 | O31: =Table4[[#This Row],[Daily Rate]]/8*1.5*Table4[[#This Row],[Weekday OVT]] -> 86381.25 | P31: =Table4[[#This Row],[Daily Rate]]/8*(1.5*Table4[[#This Row],[Total Saturday]]) -> 43190.625 | Q31: =Table4[[#This Row],[Daily Rate]]/8*(2*Table4[[#This Row],[Total Sunday]]) -> 0 | R31: =2500*Table4[[#This Row],[Night Worked]] -> 0 | S31: =500*Table4[[#This Row],[Total Weekday]] -> 12000 | Y31: =SUM(Table4[[#This Row],[Wkd Earning]:[Arrears]]) -> 466771.88 | Z31: =0.05*Table4[[#This Row],[Total Earnings]] -> 23338.594 | AA31: =Table4[[#This Row],[Total Earnings]] -> 466771.88 | AB31: =Table4[[#This Row],[Gross Salary]]-Table4[[#This Row],[WHT]] -> 443433.28
A32: C2456 | B32: OGAH | C32: IMONI | D32: RIGGER | E32: IDI - IDI_ORO | F32: 11575 | G32: 47 | H32: M | I32: 31 | J32: 0 | K32: 55 | L32: 44 | M32: 0 | N32: =Table4[[#This Row],[Total Weekday]]*Table4[[#This Row],[Daily Rate]] -> 358825 | O32: =Table4[[#This Row],[Daily Rate]]/8*1.5*Table4[[#This Row],[Weekday OVT]] -> 0 | P32: =Table4[[#This Row],[Daily Rate]]/8*(1.5*Table4[[#This Row],[Total Saturday]]) -> 119367.19 | Q32: =Table4[[#This Row],[Daily Rate]]/8*(2*Table4[[#This Row],[Total Sunday]]) -> 127325 | R32: =2500*Table4[[#This Row],[Night Worked]] -> 0 | S32: =500*Table4[[#This Row],[Total Weekday]] -> 15500 | Y32: =SUM(Table4[[#This Row],[Wkd Earning]:[Arrears]]) -> 621017.19 | Z32: =0.05*Table4[[#This Row],[Total Earnings]] -> 31050.859 | AA32: =Table4[[#This Row],[Total Earnings]] -> 621017.19 | AB32: =Table4[[#This Row],[Gross Salary]]-Table4[[#This Row],[WHT]] -> 589966.33
A33: C2462 | B33: NASIRU | C33: JAMIU | D33: WELDER | E33: IDI - IDI_ORO | F33: 20100 | G33: 58 | H33: M | I33: 22 | J33: 3 | K33: 0 | L33: 0 | M33: 0 | N33: =Table4[[#This Row],[Total Weekday]]*Table4[[#This Row],[Daily Rate]] -> 442200 | O33: =Table4[[#This Row],[Daily Rate]]/8*1.5*Table4[[#This Row],[Weekday OVT]] -> 11306.25 | P33: =Table4[[#This Row],[Daily Rate]]/8*(1.5*Table4[[#This Row],[Total Saturday]]) -> 0 | Q33: =Table4[[#This Row],[Daily Rate]]/8*(2*Table4[[#This Row],[Total Sunday]]) -> 0 | R33: =2500*Table4[[#This Row],[Night Worked]] -> 0 | S33: =500*Table4[[#This Row],[Total Weekday]] -> 11000 | Y33: =SUM(Table4[[#This Row],[Wkd Earning]:[Arrears]]) -> 464506.25 | Z33: =0.05*Table4[[#This Row],[Total Earnings]] -> 23225.312 | AA33: =Table4[[#This Row],[Total Earnings]] -> 464506.25 | AB33: =Table4[[#This Row],[Gross Salary]]-Table4[[#This Row],[WHT]] -> 441280.94
A34: C2470 | B34: YEKINI | C34: LAWAL | D34: BURNER | E34: IDI - IDI_ORO | F34: 10250 | G34: 64 | H34: M | I34: 22 | J34: 10 | K34: 0 | L34: 0 | M34: 0 | N34: =Table4[[#This Row],[Total Weekday]]*Table4[[#This Row],[Daily Rate]] -> 225500 | O34: =Table4[[#This Row],[Daily Rate]]/8*1.5*Table4[[#This Row],[Weekday OVT]] -> 19218.75 | P34: =Table4[[#This Row],[Daily Rate]]/8*(1.5*Table4[[#This Row],[Total Saturday]]) -> 0 | Q34: =Table4[[#This Row],[Daily Rate]]/8*(2*Table4[[#This Row],[Total Sunday]]) -> 0 | R34: =2500*Table4[[#This Row],[Night Worked]] -> 0 | S34: =500*Table4[[#This Row],[Total Weekday]] -> 11000 | Y34: =SUM(Table4[[#This Row],[Wkd Earning]:[Arrears]]) -> 255718.75 | Z34: =0.05*Table4[[#This Row],[Total Earnings]] -> 12785.938 | AA34: =Table4[[#This Row],[Total Earnings]] -> 255718.75 | AB34: =Table4[[#This Row],[Gross Salary]]-Table4[[#This Row],[WHT]] -> 242932.81
A35: C2477 | B35: GAMBO | C35: MOHAMMED | D35: SCAFFOLDER | E35: IDI - IDI_ORO | F35: 13250 | G35: 46 | H35: M | I35: 22 | J35: 7 | K35: 0 | L35: 0 | M35: 0 | N35: =Table4[[#This Row],[Total Weekday]]*Table4[[#This Row],[Daily Rate]] -> 291500 | O35: =Table4[[#This Row],[Daily Rate]]/8*1.5*Table4[[#This Row],[Weekday OVT]] -> 17390.625 | P35: =Table4[[#This Row],[Daily Rate]]/8*(1.5*Table4[[#This Row],[Total Saturday]]) -> 0 | Q35: =Table4[[#This Row],[Daily Rate]]/8*(2*Table4[[#This Row],[Total Sunday]]) -> 0 | R35: =2500*Table4[[#This Row],[Night Worked]] -> 0 | S35: =500*Table4[[#This Row],[Total Weekday]] -> 11000 | Y35: =SUM(Table4[[#This Row],[Wkd Earning]:[Arrears]]) -> 319890.62 | Z35: =0.05*Table4[[#This Row],[Total Earnings]] -> 15994.531 | AA35: =Table4[[#This Row],[Total Earnings]] -> 319890.62 | AB35: =Table4[[#This Row],[Gross Salary]]-Table4[[#This Row],[WHT]] -> 303896.09
A36: C2492 | B36: TIMOTHY | C36: OGWUA | D36: ELECTRICIAN | E36: IDI - IDI_ORO | F36: 10250 | G36: 48 | H36: M | I36: 28 | J36: 40 | K36: 35 | L36: 10 | M36: 6 | N36: =Table4[[#This Row],[Total Weekday]]*Table4[[#This Row],[Daily Rate]] -> 287000 | O36: =Table4[[#This Row],[Daily Rate]]/8*1.5*Table4[[#This Row],[Weekday OVT]] -> 76875 | P36: =Table4[[#This Row],[Daily Rate]]/8*(1.5*Table4[[#This Row],[Total Saturday]]) -> 67265.625 | Q36: =Table4[[#This Row],[Daily Rate]]/8*(2*Table4[[#This Row],[Total Sunday]]) -> 25625 | R36: =2500*Table4[[#This Row],[Night Worked]] -> 15000 | S36: =500*Table4[[#This Row],[Total Weekday]] -> 14000 | Y36: =SUM(Table4[[#This Row],[Wkd Earning]:[Arrears]]) -> 485765.62 | Z36: =0.05*Table4[[#This Row],[Total Earnings]] -> 24288.281 | AA36: =Table4[[#This Row],[Total Earnings]] -> 485765.62 | AB36: =Table4[[#This Row],[Gross Salary]]-Table4[[#This Row],[WHT]] -> 461477.34
A37: C2507 | B37: CHINEMERE | C37: ONWUNTA | D37: 6G WELDER | E37: IDI - IDI_ORO | F37: 16700 | G37: 62 | H37: M | I37: 22 | J37: 3 | K37: 0 | L37: 0 | M37: 0 | N37: =Table4[[#This Row],[Total Weekday]]*Table4[[#This Row],[Daily Rate]] -> 367400 | O37: =Table4[[#This Row],[Daily Rate]]/8*1.5*Table4[[#This Row],[Weekday OVT]] -> 9393.75 | P37: =Table4[[#This Row],[Daily Rate]]/8*(1.5*Table4[[#This Row],[Total Saturday]]) -> 0 | Q37: =Table4[[#This Row],[Daily Rate]]/8*(2*Table4[[#This Row],[Total Sunday]]) -> 0 | R37: =2500*Table4[[#This Row],[Night Worked]] -> 0 | S37: =500*Table4[[#This Row],[Total Weekday]] -> 11000 | T37: 4000 | Y37: =SUM(Table4[[#This Row],[Wkd Earning]:[Arrears]]) -> 391793.75 | Z37: =0.05*Table4[[#This Row],[Total Earnings]] -> 19589.688 | AA37: =Table4[[#This Row],[Total Earnings]] -> 391793.75 | AB37: =Table4[[#This Row],[Gross Salary]]-Table4[[#This Row],[WHT]] -> 372204.06
A38: C2515 | B38: KAZEEM | C38: OYEWOLE | D38: RIGGER | E38: IDI - IDI_ORO | F38: 11575 | G38: 46 | H38: M | I38: 22 | J38: 15 | K38: 0 | L38: 0 | M38: 0 | N38: =Table4[[#This Row],[Total Weekday]]*Table4[[#This Row],[Daily Rate]] -> 254650 | O38: =Table4[[#This Row],[Daily Rate]]/8*1.5*Table4[[#This Row],[Weekday OVT]] -> 32554.688 | P38: =Table4[[#This Row],[Daily Rate]]/8*(1.5*Table4[[#This Row],[Total Saturday]]) -> 0 | Q38: =Table4[[#This Row],[Daily Rate]]/8*(2*Table4[[#This Row],[Total Sunday]]) -> 0 | R38: =2500*Table4[[#This Row],[Night Worked]] -> 0 | S38: =500*Table4[[#This Row],[Total Weekday]] -> 11000 | Y38: =SUM(Table4[[#This Row],[Wkd Earning]:[Arrears]]) -> 298204.69 | Z38: =0.05*Table4[[#This Row],[Total Earnings]] -> 14910.234 | AA38: =Table4[[#This Row],[Total Earnings]] -> 298204.69 | AB38: =Table4[[#This Row],[Gross Salary]]-Table4[[#This Row],[WHT]] -> 283294.45
A39: C2526 | B39: ABLE | C39: ROMANUS | D39: FITTER MATE | E39: IDI - IDI_ORO | F39: 10812 | G39: 26 | H39: M | I39: 24 | J39: 26 | K39: 15 | L39: 0 | M39: 0 | N39: =Table4[[#This Row],[Total Weekday]]*Table4[[#This Row],[Daily Rate]] -> 259488 | O39: =Table4[[#This Row],[Daily Rate]]/8*1.5*Table4[[#This Row],[Weekday OVT]] -> 52708.5 | P39: =Table4[[#This Row],[Daily Rate]]/8*(1.5*Table4[[#This Row],[Total Saturday]]) -> 30408.75 | Q39: =Table4[[#This Row],[Daily Rate]]/8*(2*Table4[[#This Row],[Total Sunday]]) -> 0 | R39: =2500*Table4[[#This Row],[Night Worked]] -> 0 | S39: =500*Table4[[#This Row],[Total Weekday]] -> 12000 | Y39: =SUM(Table4[[#This Row],[Wkd Earning]:[Arrears]]) -> 354605.25 | Z39: =0.05*Table4[[#This Row],[Total Earnings]] -> 17730.263 | AA39: =Table4[[#This Row],[Total Earnings]] -> 354605.25 | AB39: =Table4[[#This Row],[Gross Salary]]-Table4[[#This Row],[WHT]] -> 336874.99
A40: C2536 | B40: EMMANUEL | C40: SUNDAY | D40: FITTER MATE | E40: IDI - IDI_ORO | F40: 10812 | G40: 31 | H40: M | I40: 25 | J40: 27 | K40: 0 | L40: 0 | M40: 0 | N40: =Table4[[#This Row],[Total Weekday]]*Table4[[#This Row],[Daily Rate]] -> 270300 | O40: =Table4[[#This Row],[Daily Rate]]/8*1.5*Table4[[#This Row],[Weekday OVT]] -> 54735.75 | P40: =Table4[[#This Row],[Daily Rate]]/8*(1.5*Table4[[#This Row],[Total Saturday]]) -> 0 | Q40: =Table4[[#This Row],[Daily Rate]]/8*(2*Table4[[#This Row],[Total Sunday]]) -> 0 | R40: =2500*Table4[[#This Row],[Night Worked]] -> 0 | S40: =500*Table4[[#This Row],[Total Weekday]] -> 12500 | Y40: =SUM(Table4[[#This Row],[Wkd Earning]:[Arrears]]) -> 337535.75 | Z40: =0.05*Table4[[#This Row],[Total Earnings]] -> 16876.788 | AA40: =Table4[[#This Row],[Total Earnings]] -> 337535.75 | AB40: =Table4[[#This Row],[Gross Salary]]-Table4[[#This Row],[WHT]] -> 320658.96
A41: C2537 | B41: SIMIRE | C41: SUNDAY | D41: ELECTRICIAN | E41: IDI - IDI_ORO | F41: 10250 | G41: 55 | H41: M | I41: 29 | J41: 57 | K41: 33 | L41: 20 | M41: 12 | N41: =Table4[[#This Row],[Total Weekday]]*Table4[[#This Row],[Daily Rate]] -> 297250 | O41: =Table4[[#This Row],[Daily Rate]]/8*1.5*Table4[[#This Row],[Weekday OVT]] -> 109546.88 | P41: =Table4[[#This Row],[Daily Rate]]/8*(1.5*Table4[[#This Row],[Total Saturday]]) -> 63421.875 | Q41: =Table4[[#This Row],[Daily Rate]]/8*(2*Table4[[#This Row],[Total Sunday]]) -> 51250 | R41: =2500*Table4[[#This Row],[Night Worked]] -> 30000 | S41: =500*Table4[[#This Row],[Total Weekday]] -> 14500 | Y41: =SUM(Table4[[#This Row],[Wkd Earning]:[Arrears]]) -> 565968.75 | Z41: =0.05*Table4[[#This Row],[Total Earnings]] -> 28298.438 | AA41: =Table4[[#This Row],[Total Earnings]] -> 565968.75 | AB41: =Table4[[#This Row],[Gross Salary]]-Table4[[#This Row],[WHT]] -> 537670.31
A42: C2604 | B42: PATRICK | C42: ADAH | D42: FITTER MATE | E42: IDI - IDI_ORO | F42: 13050 | G42: 38 | H42: M | I42: 22 | J42: 16 | K42: 0 | L42: 0 | M42: 0 | N42: =Table4[[#This Row],[Total Weekday]]*Table4[[#This Row],[Daily Rate]] -> 287100 | O42: =Table4[[#This Row],[Daily Rate]]/8*1.5*Table4[[#This Row],[Weekday OVT]] -> 39150 | P42: =Table4[[#This Row],[Daily Rate]]/8*(1.5*Table4[[#This Row],[Total Saturday]]) -> 0 | Q42: =Table4[[#This Row],[Daily Rate]]/8*(2*Table4[[#This Row],[Total Sunday]]) -> 0 | R42: =2500*Table4[[#This Row],[Night Worked]] -> 0 | S42: =500*Table4[[#This Row],[Total Weekday]] -> 11000 | Y42: =SUM(Table4[[#This Row],[Wkd Earning]:[Arrears]]) -> 337250 | Z42: =0.05*Table4[[#This Row],[Total Earnings]] -> 16862.5 | AA42: =Table4[[#This Row],[Total Earnings]] -> 337250 | AB42: =Table4[[#This Row],[Gross Salary]]-Table4[[#This Row],[WHT]] -> 320387.5
A43: C2080 | B43: LATEEF | C43: OYELEYE | D43: RIGGER | E43: IDI - IDI_ORO | F43: 13150 | G43: 43 | H43: M | I43: 21 | J43: 4 | K43: 0 | L43: 0 | M43: 0 | N43: =Table4[[#This Row],[Total Weekday]]*Table4[[#This Row],[Daily Rate]] -> 276150 | O43: =Table4[[#This Row],[Daily Rate]]/8*1.5*Table4[[#This Row],[Weekday OVT]] -> 9862.5 | P43: =Table4[[#This Row],[Daily Rate]]/8*(1.5*Table4[[#This Row],[Total Saturday]]) -> 0 | Q43: =Table4[[#This Row],[Daily Rate]]/8*(2*Table4[[#This Row],[Total Sunday]]) -> 0 | R43: =2500*Table4[[#This Row],[Night Worked]] -> 0 | S43: =500*Table4[[#This Row],[Total Weekday]] -> 10500 | Y43: =SUM(Table4[[#This Row],[Wkd Earning]:[Arrears]]) -> 296512.5 | Z43: =0.05*Table4[[#This Row],[Total Earnings]] -> 14825.625 | AA43: =Table4[[#This Row],[Total Earnings]] -> 296512.5 | AB43: =Table4[[#This Row],[Gross Salary]]-Table4[[#This Row],[WHT]] -> 281686.88
A44: C2622 | B44: AUDU | C44: JOHN | D44: RIGGER | E44: IDI - IDI_ORO | F44: 11575 | G44: 39 | H44: M | I44: 22 | J44: 0 | K44: 0 | L44: 0 | M44: 0 | N44: =Table4[[#This Row],[Total Weekday]]*Table4[[#This Row],[Daily Rate]] -> 254650 | O44: =Table4[[#This Row],[Daily Rate]]/8*1.5*Table4[[#This Row],[Weekday OVT]] -> 0 | P44: =Table4[[#This Row],[Daily Rate]]/8*(1.5*Table4[[#This Row],[Total Saturday]]) -> 0 | Q44: =Table4[[#This Row],[Daily Rate]]/8*(2*Table4[[#This Row],[Total Sunday]]) -> 0 | R44: =2500*Table4[[#This Row],[Night Worked]] -> 0 | S44: =500*Table4[[#This Row],[Total Weekday]] -> 11000 | Y44: =SUM(Table4[[#This Row],[Wkd Earning]:[Arrears]]) -> 265650 | Z44: =0.05*Table4[[#This Row],[Total Earnings]] -> 13282.5 | AA44: =Table4[[#This Row],[Total Earnings]] -> 265650 | AB44: =Table4[[#This Row],[Gross Salary]]-Table4[[#This Row],[WHT]] -> 252367.5
A45: C2626 | B45: BONIFACE | C45: OKPE | D45: SCAFFOLDER | E45: IDI - IDI_ORO | F45: 13250 | G45: 56 | H45: M | I45: 22 | J45: 12 | K45: 0 | L45: 0 | M45: 0 | N45: =Table4[[#This Row],[Total Weekday]]*Table4[[#This Row],[Daily Rate]] -> 291500 | O45: =Table4[[#This Row],[Daily Rate]]/8*1.5*Table4[[#This Row],[Weekday OVT]] -> 29812.5 | P45: =Table4[[#This Row],[Daily Rate]]/8*(1.5*Table4[[#This Row],[Total Saturday]]) -> 0 | Q45: =Table4[[#This Row],[Daily Rate]]/8*(2*Table4[[#This Row],[Total Sunday]]) -> 0 | R45: =2500*Table4[[#This Row],[Night Worked]] -> 0 | S45: =500*Table4[[#This Row],[Total Weekday]] -> 11000 | Y45: =SUM(Table4[[#This Row],[Wkd Earning]:[Arrears]]) -> 332312.5 | Z45: =0.05*Table4[[#This Row],[Total Earnings]] -> 16615.625 | AA45: =Table4[[#This Row],[Total Earnings]] -> 332312.5 | AB45: =Table4[[#This Row],[Gross Salary]]-Table4[[#This Row],[WHT]] -> 315696.88
A46: C2724 | B46: MOSES | C46: AMANOKHAI | D46: FITTER MATE | E46: IDI - IDI_ORO | F46: 11575 | G46: 33 | H46: M | I46: 22 | J46: 25 | K46: 0 | L46: 0 | M46: 0 | N46: =Table4[[#This Row],[Total Weekday]]*Table4[[#This Row],[Daily Rate]] -> 254650 | O46: =Table4[[#This Row],[Daily Rate]]/8*1.5*Table4[[#This Row],[Weekday OVT]] -> 54257.812 | P46: =Table4[[#This Row],[Daily Rate]]/8*(1.5*Table4[[#This Row],[Total Saturday]]) -> 0 | Q46: =Table4[[#This Row],[Daily Rate]]/8*(2*Table4[[#This Row],[Total Sunday]]) -> 0 | R46: =2500*Table4[[#This Row],[Night Worked]] -> 0 | S46: =500*Table4[[#This Row],[Total Weekday]] -> 11000 | Y46: =SUM(Table4[[#This Row],[Wkd Earning]:[Arrears]]) -> 319907.81 | Z46: =0.05*Table4[[#This Row],[Total Earnings]] -> 15995.391 | AA46: =Table4[[#This Row],[Total Earnings]] -> 319907.81 | AB46: =Table4[[#This Row],[Gross Salary]]-Table4[[#This Row],[WHT]] -> 303912.42
A47: C2725 | B47: HENRY | C47: AMODU | D47: RIGGER AND CRANE OPERATOR | E47: IDI - IDI_ORO | F47: 11575 | G47: 51 | H47: M | I47: 23 | J47: 13 | K47: 8 | L47: 0 | M47: 0 | N47: =Table4[[#This Row],[Total Weekday]]*Table4[[#This Row],[Daily Rate]] -> 266225 | O47: =Table4[[#This Row],[Daily Rate]]/8*1.5*Table4[[#This Row],[Weekday OVT]] -> 28214.062 | P47: =Table4[[#This Row],[Daily Rate]]/8*(1.5*Table4[[#This Row],[Total Saturday]]) -> 17362.5 | Q47: =Table4[[#This Row],[Daily Rate]]/8*(2*Table4[[#This Row],[Total Sunday]]) -> 0 | R47: =2500*Table4[[#This Row],[Night Worked]] -> 0 | S47: =500*Table4[[#This Row],[Total Weekday]] -> 11500 | Y47: =SUM(Table4[[#This Row],[Wkd Earning]:[Arrears]]) -> 323301.56 | Z47: =0.05*Table4[[#This Row],[Total Earnings]] -> 16165.078 | AA47: =Table4[[#This Row],[Total Earnings]] -> 323301.56 | AB47: =Table4[[#This Row],[Gross Salary]]-Table4[[#This Row],[WHT]] -> 307136.48
...

Sheet DLPC
A1: Emp. Code | B1: First Name | C1: Last Name | D1: Job Title | E1: Daily Rate | F1: Age | G1: Gender | H1: Total Weekday | I1: Weekday OVT | J1: Total Saturday | K1: Total Sunday | L1: Public Holiday | M1: Night Worked | N1: Wkd Earning | O1: Wkd Ovt Amt | P1: Sat Ovt Amt | Q1: Sun Ovt Amt | R1: PH Amt | S1: Night Amt | T1: Meal Allowance | U1: Transport | V1: Total Earnings | W1: WHT | X1: Gross Salary | Y1: Net Pay
A2: C2408 | B2: LAWRENCE | C2: ANTHONY | D2: SKIMMER TECHNICIAN | E2: 10000 | F2: 48 | G2: M | H2: 22 | I2: 4 | J2: 0 | K2: 0 | M2: 0 | N2: =Table52[[#This Row],[Total Weekday]]*Table52[[#This Row],[Daily Rate]] -> 220000 | O2: =Table52[[#This Row],[Daily Rate]]/8*(1.5*Table52[[#This Row],[Weekday OVT]]) -> 7500 | P2: =Table52[[#This Row],[Daily Rate]]/8*(1.5*Table52[[#This Row],[Total Saturday]]) -> 0 | Q2: =Table52[[#This Row],[Daily Rate]]/8*(2*Table52[[#This Row],[Total Sunday]]) -> 0 | R2: =Table52[[#This Row],[Daily Rate]]/8*(2*Table52[[#This Row],[Public Holiday]]) -> 0 | S2: =1100*Table52[[#This Row],[Night Worked]] -> 0 | T2: =500*Table52[[#This Row],[Total Weekday]] -> 11000 | U2: 0 | V2: =SUM(Table52[[#This Row],[Wkd Earning]:[Transport]]) -> 238500 | W2: =0.05*Table52[[#This Row],[Total Earnings]] -> 11925 | X2: =Table52[[#This Row],[Total Earnings]] -> 238500 | Y2: =Table52[[#This Row],[Gross Salary]]-Table52[[#This Row],[WHT]] -> 226575
A3: C2443 | B3: ADEBIYI | C3: GANIYU | D3: KETTLE | E3: 9500 | F3: 37 | G3: M | H3: 21 | I3: 0 | J3: 6 | K3: 0 | M3: 0 | N3: =Table52[[#This Row],[Total Weekday]]*Table52[[#This Row],[Daily Rate]] -> 199500 | O3: =Table52[[#This Row],[Daily Rate]]/8*(1.5*Table52[[#This Row],[Weekday OVT]]) -> 0 | P3: =Table52[[#This Row],[Daily Rate]]/8*(1.5*Table52[[#This Row],[Total Saturday]]) -> 10687.5 | Q3: =Table52[[#This Row],[Daily Rate]]/8*(2*Table52[[#This Row],[Total Sunday]]) -> 0 | R3: =Table52[[#This Row],[Daily Rate]]/8*(2*Table52[[#This Row],[Public Holiday]]) -> 0 | S3: =1100*Table52[[#This Row],[Night Worked]] -> 0 | T3: =500*Table52[[#This Row],[Total Weekday]] -> 10500 | U3: 0 | V3: =SUM(Table52[[#This Row],[Wkd Earning]:[Transport]]) -> 220687.5 | W3: =0.05*Table52[[#This Row],[Total Earnings]] -> 11034.375 | X3: =Table52[[#This Row],[Total Earnings]] -> 220687.5 | Y3: =Table52[[#This Row],[Gross Salary]]-Table52[[#This Row],[WHT]] -> 209653.12
A4: C2506 | B4: MICHEAL | C4: ONOJA | D4: KETTLE | E4: 9500 | F4: 29 | G4: M | H4: 22 | I4: 2 | J4: 0 | K4: 0 | M4: 0 | N4: =Table52[[#This Row],[Total Weekday]]*Table52[[#This Row],[Daily Rate]] -> 209000 | O4: =Table52[[#This Row],[Daily Rate]]/8*(1.5*Table52[[#This Row],[Weekday OVT]]) -> 3562.5 | P4: =Table52[[#This Row],[Daily Rate]]/8*(1.5*Table52[[#This Row],[Total Saturday]]) -> 0 | Q4: =Table52[[#This Row],[Daily Rate]]/8*(2*Table52[[#This Row],[Total Sunday]]) -> 0 | R4: =Table52[[#This Row],[Daily Rate]]/8*(2*Table52[[#This Row],[Public Holiday]]) -> 0 | S4: =1100*Table52[[#This Row],[Night Worked]] -> 0 | T4: =500*Table52[[#This Row],[Total Weekday]] -> 11000 | U4: 0 | V4: =SUM(Table52[[#This Row],[Wkd Earning]:[Transport]]) -> 223562.5 | W4: =0.05*Table52[[#This Row],[Total Earnings]] -> 11178.125 | X4: =Table52[[#This Row],[Total Earnings]] -> 223562.5 | Y4: =Table52[[#This Row],[Gross Salary]]-Table52[[#This Row],[WHT]] -> 212384.38
A5: C2512 | B5: SUNDAY | C5: OVAT | D5: QC ASSISTANCE | E5: 8600 | F5: 25 | G5: M | H5: 22 | I5: 28 | J5: 14 | K5: 0 | M5: 0 | N5: =Table52[[#This Row],[Total Weekday]]*Table52[[#This Row],[Daily Rate]] -> 189200 | O5: =Table52[[#This Row],[Daily Rate]]/8*(1.5*Table52[[#This Row],[Weekday OVT]]) -> 45150 | P5: =Table52[[#This Row],[Daily Rate]]/8*(1.5*Table52[[#This Row],[Total Saturday]]) -> 22575 | Q5: =Table52[[#This Row],[Daily Rate]]/8*(2*Table52[[#This Row],[Total Sunday]]) -> 0 | R5: =Table52[[#This Row],[Daily Rate]]/8*(2*Table52[[#This Row],[Public Holiday]]) -> 0 | S5: =1100*Table52[[#This Row],[Night Worked]] -> 0 | T5: =500*Table52[[#This Row],[Total Weekday]] -> 11000 | U5: 0 | V5: =SUM(Table52[[#This Row],[Wkd Earning]:[Transport]]) -> 267925 | W5: =0.05*Table52[[#This Row],[Total Earnings]] -> 13396.25 | X5: =Table52[[#This Row],[Total Earnings]] -> 267925 | Y5: =Table52[[#This Row],[Gross Salary]]-Table52[[#This Row],[WHT]] -> 254528.75
A6: C2396 | B6: MUSBAU | C6: AKINDELE | D6: KETTLE | E6: 9500 | F6: 37 | G6: M | H6: 22 | I6: 2 | J6: 0 | K6: 0 | M6: 0 | N6: =Table52[[#This Row],[Total Weekday]]*Table52[[#This Row],[Daily Rate]] -> 209000 | O6: =Table52[[#This Row],[Daily Rate]]/8*(1.5*Table52[[#This Row],[Weekday OVT]]) -> 3562.5 | P6: =Table52[[#This Row],[Daily Rate]]/8*(1.5*Table52[[#This Row],[Total Saturday]]) -> 0 | Q6: =Table52[[#This Row],[Daily Rate]]/8*(2*Table52[[#This Row],[Total Sunday]]) -> 0 | R6: =Table52[[#This Row],[Daily Rate]]/8*(2*Table52[[#This Row],[Public Holiday]]) -> 0 | S6: =1100*Table52[[#This Row],[Night Worked]] -> 0 | T6: =500*Table52[[#This Row],[Total Weekday]] -> 11000 | U6: 0 | V6: =SUM(Table52[[#This Row],[Wkd Earning]:[Transport]]) -> 223562.5 | W6: =0.05*Table52[[#This Row],[Total Earnings]] -> 11178.125 | X6: =Table52[[#This Row],[Total Earnings]] -> 223562.5 | Y6: =Table52[[#This Row],[Gross Salary]]-Table52[[#This Row],[WHT]] -> 212384.38
A7: C2394 | B7: AHMED | C7: IDOWU | D7: KETTLE | E7: 9500 | F7: 34 | G7: M | H7: 22 | I7: 6 | J7: 6 | K7: 0 | M7: 0 | N7: =Table52[[#This Row],[Total Weekday]]*Table52[[#This Row],[Daily Rate]] -> 209000 | O7: =Table52[[#This Row],[Daily Rate]]/8*(1.5*Table52[[#This Row],[Weekday OVT]]) -> 10687.5 | P7: =Table52[[#This Row],[Daily Rate]]/8*(1.5*Table52[[#This Row],[Total Saturday]]) -> 10687.5 | Q7: =Table52[[#This Row],[Daily Rate]]/8*(2*Table52[[#This Row],[Total Sunday]]) -> 0 | R7: =Table52[[#This Row],[Daily Rate]]/8*(2*Table52[[#This Row],[Public Holiday]]) -> 0 | S7: =1100*Table52[[#This Row],[Night Worked]] -> 0 | T7: =500*Table52[[#This Row],[Total Weekday]] -> 11000 | U7: 0 | V7: =SUM(Table52[[#This Row],[Wkd Earning]:[Transport]]) -> 241375 | W7: =0.05*Table52[[#This Row],[Total Earnings]] -> 12068.75 | X7: =Table52[[#This Row],[Total Earnings]] -> 241375 | Y7: =Table52[[#This Row],[Gross Salary]]-Table52[[#This Row],[WHT]] -> 229306.25
A8: C2522 | B8: RASAK | C8: JAMIU | D8: KETTLE | E8: 9500 | F8: 42 | G8: M | H8: 22 | I8: 6 | J8: 6 | K8: 0 | M8: 0 | N8: =Table52[[#This Row],[Total Weekday]]*Table52[[#This Row],[Daily Rate]] -> 209000 | O8: =Table52[[#This Row],[Daily Rate]]/8*(1.5*Table52[[#This Row],[Weekday OVT]]) -> 10687.5 | P8: =Table52[[#This Row],[Daily Rate]]/8*(1.5*Table52[[#This Row],[Total Saturday]]) -> 10687.5 | Q8: =Table52[[#This Row],[Daily Rate]]/8*(2*Table52[[#This Row],[Total Sunday]]) -> 0 | R8: =Table52[[#This Row],[Daily Rate]]/8*(2*Table52[[#This Row],[Public Holiday]]) -> 0 | S8: =1100*Table52[[#This Row],[Night Worked]] -> 0 | T8: =500*Table52[[#This Row],[Total Weekday]] -> 11000 | U8: 0 | V8: =SUM(Table52[[#This Row],[Wkd Earning]:[Transport]]) -> 241375 | W8: =0.05*Table52[[#This Row],[Total Earnings]] -> 12068.75 | X8: =Table52[[#This Row],[Total Earnings]] -> 241375 | Y8: =Table52[[#This Row],[Gross Salary]]-Table52[[#This Row],[WHT]] -> 229306.25
A9: =SUBTOTAL(103,Table52[Emp. Code]) -> 7 | E9: =SUBTOTAL(109,Table52[Daily Rate]) -> 66100 | H9: =SUBTOTAL(109,Table52[Total Weekday]) -> 153 | I9: =SUBTOTAL(109,Table52[Weekday OVT]) -> 48 | J9: =SUBTOTAL(109,Table52[Total Saturday]) -> 32 | N9: =SUBTOTAL(109,Table52[Wkd Earning]) -> 1444700 | O9: =SUBTOTAL(109,Table52[Wkd Ovt Amt]) -> 81150 | P9: =SUBTOTAL(109,Table52[Sat Ovt Amt]) -> 54637.5 | Q9: =SUBTOTAL(109,Table52[Sun Ovt Amt]) -> 0 | R9: =SUBTOTAL(109,Table52[PH Amt]) -> 0 | S9: =SUBTOTAL(109,Table52[Night Amt]) -> 0 | T9: =SUBTOTAL(109,Table52[Meal Allowance]) -> 76500 | U9: =SUBTOTAL(109,Table52[Transport]) -> 0 | V9: =SUBTOTAL(109,Table52[Total Earnings]) -> 1656987.5 | W9: =SUBTOTAL(109,Table52[WHT]) -> 82849.375 | X9: =SUBTOTAL(109,Table52[Gross Salary]) -> 1656987.5 | Y9: =SUBTOTAL(109,Table52[Net Pay]) -> 1574138.1

Sheet DLE BANK SCHD
A1: Employee Bank Details
A2: Employee Code | B2: Employee Name | C2: Bank | D2: Account No | E2: Sort Code | F2: NET Salary
A3: C0129 | B3: KALU AGWU OKWARA OKWARA | C3: Fidelity Bank Plc | D3: 4020099243 | E3: 070150003 | F3: =_xlfn.XLOOKUP(Table13[[#This Row],[Employee Code]],DLE!A:A,DLE!AB:AB) -> 311089.38
A4: C0293 | B4: OLANIYAN OLAKUNLE | C4: Guaranty Trust Bank Plc | D4: 0128756772 | E4: 058152052 | F4: =_xlfn.XLOOKUP(Table13[[#This Row],[Employee Code]],DLE!A:A,DLE!AB:AB) -> 461492.19
A5: C0585 | B5: FEMI BELLO | C5: Access Bank Plc | D5: 0000214630 | E5: 044150149 | F5: =_xlfn.XLOOKUP(Table13[[#This Row],[Employee Code]],DLE!A:A,DLE!AB:AB) -> 349030
A6: C0974 | B6: ETUERI STEPHEN | C6: Zenith Bank Plc | D6: 2082484750 | E6: 1 | F6: =_xlfn.XLOOKUP(Table13[[#This Row],[Employee Code]],DLE!A:A,DLE!AB:AB) -> 383515
A7: C1035 | B7: EJEH DONATUS | C7: Guaranty Trust Bank Plc | D7: 0147788781 | E7: 058152052 | F7: =_xlfn.XLOOKUP(Table13[[#This Row],[Employee Code]],DLE!A:A,DLE!AB:AB) -> 308708.44
A8: C1065 | B8: OGHENERIE VINCENT | C8: Fidelity Bank Plc | D8: 6050577180 | E8: 070150003 | F8: =_xlfn.XLOOKUP(Table13[[#This Row],[Employee Code]],DLE!A:A,DLE!AB:AB) -> 336629.53
A9: C1144 | B9: OGWUA CHRIS | C9: Fidelity Bank Plc | D9: 6231398469 | E9: 070150003 | F9: =_xlfn.XLOOKUP(Table13[[#This Row],[Employee Code]],DLE!A:A,DLE!AB:AB) -> 298472.19
A10: C1162 | B10: ADEKOYA ADEWALE | C10: Polaris Bank | D10: 3011580494 | E10: 076151006 | F10: =_xlfn.XLOOKUP(Table13[[#This Row],[Employee Code]],DLE!A:A,DLE!AB:AB) -> 669304.69
A11: C1491 | B11: VINCENT NNAMDI | C11: Fidelity Bank Plc | D11: 4020099542 | E11: 070150003 | F11: =_xlfn.XLOOKUP(Table13[[#This Row],[Employee Code]],DLE!A:A,DLE!AB:AB) -> 242932.81
A12: C1533 | B12: OKEKE VINCENT | C12: Stanbic IBTC Bank Plc | D12: 0033804939 | E12: 221150014 | F12: =_xlfn.XLOOKUP(Table13[[#This Row],[Employee Code]],DLE!A:A,DLE!AB:AB) -> 344850
A13: C1612 | B13: MBAMARA RICHARD | C13: Fidelity Bank Plc | D13: 6237537987 | E13: 070150003 | F13: =_xlfn.XLOOKUP(Table13[[#This Row],[Employee Code]],DLE!A:A,DLE!AB:AB) -> 471675
A14: C1705 | B14: ROTIMI MATTHEW | C14: Guaranty Trust Bank Plc | D14: 0212808307 | E14: 058152052 | F14: =_xlfn.XLOOKUP(Table13[[#This Row],[Employee Code]],DLE!A:A,DLE!AB:AB) -> 454396.88
... A178: C2087 | B178: NKANU THOMPSON | C178: United Bank for Africa Plc | D178: 2039233996 | E178: 033150011 | F178: =_xlfn.XLOOKUP(Table13[[#This Row],[Employee Code]],DLE!A:A,DLE!AB:AB) -> 334126.88
A179: C2822 | B179: EBIALE VINCENT | F179: =_xlfn.XLOOKUP(Table13[[#This Row],[Employee Code]],DLE!A:A,DLE!AB:AB) -> 155948.44
A180: C2825 | B180: ISMAIL AKANDE | C180: United Bank for Africa Plc | D180: 2382677353 | F180: =_xlfn.XLOOKUP(Table13[[#This Row],[Employee Code]],DLE!A:A,DLE!AB:AB) -> 186188.12
A181: C2096 | B181: SUNDAY OWOLABI | C181: Zenith Bank Plc | D181: 2266705437 | F181: =_xlfn.XLOOKUP(Table13[[#This Row],[Employee Code]],DLE!A:A,DLE!AB:AB) -> 62937.5
A182: C2827 | B182: CHARLES AKAKA | C182: Zenith Bank Plc | D182: 2193745140 | F182: =_xlfn.XLOOKUP(Table13[[#This Row],[Employee Code]],DLE!A:A,DLE!AB:AB) -> 62937.5
A183: C2826 | B183: TUNDE OYEWOLE | C183: Fidelity Bank Plc | D183: 6160491811 | F183: =_xlfn.XLOOKUP(Table13[[#This Row],[Employee Code]],DLE!A:A,DLE!AB:AB) -> 62937.5
A184: =SUBTOTAL(103,Table13[Employee Code]) -> 181 | F184: =SUBTOTAL(109,Table13[NET Salary]) -> 64985862

Sheet DLPC.BANK.SCHD
A1: Employee Bank Details
A2: Employee Code | B2: Employee Name | C2: Bank | D2: Account No | E2: Sort Code | F2: NET Salary | G2: Location
A3: C2394 | B3: HAMMED IDOWU | C3: Guaranty Trust Bank Plc | D3: 0729570216 | E3: 058152052 | F3: =_xlfn.XLOOKUP(Table146[[#This Row],[Employee Code]],Table52[Emp. Code],Table52[Net Pay]) -> 229306.25 | G3: AGEGE - AGEGE
A4: C2396 | B4: AKINDELE MUSBAU | C4: Fidelity Bank Plc | D4: 5330178152 | E4: 070150003 | F4: =_xlfn.XLOOKUP(Table146[[#This Row],[Employee Code]],Table52[Emp. Code],Table52[Net Pay]) -> 212384.38 | G4: AGEGE - AGEGE
A5: C2408 | B5: ANTHONY LAWRENCE | C5: Guaranty Trust Bank Plc | D5: 0742476502 | E5: 058152052 | F5: =_xlfn.XLOOKUP(Table146[[#This Row],[Employee Code]],Table52[Emp. Code],Table52[Net Pay]) -> 226575 | G5: AGEGE - AGEGE
A6: C2443 | B6: GANIYU ADEBIYI | C6: Guaranty Trust Bank Plc | D6: 0254241197 | E6: 058152052 | F6: =_xlfn.XLOOKUP(Table146[[#This Row],[Employee Code]],Table52[Emp. Code],Table52[Net Pay]) -> 209653.12 | G6: AGEGE - AGEGE
A7: C2506 | B7: ONOJA MICHAEL | C7: Guaranty Trust Bank Plc | D7: 0797313568 | E7: 058152052 | F7: =_xlfn.XLOOKUP(Table146[[#This Row],[Employee Code]],Table52[Emp. Code],Table52[Net Pay]) -> 212384.38 | G7: AGEGE - AGEGE
A8: C2512 | B8: OVAT SUNDAY | C8: Zenith Bank Plc | D8: 4243185836 | E8: 1 | F8: =_xlfn.XLOOKUP(Table146[[#This Row],[Employee Code]],Table52[Emp. Code],Table52[Net Pay]) -> 254528.75 | G8: AGEGE - AGEGE
A9: C2522 | B9: RASAK JAMIU | C9: Guaranty Trust Bank Plc | D9: 0743000458 | E9: 058152052 | F9: =_xlfn.XLOOKUP(Table146[[#This Row],[Employee Code]],Table52[Emp. Code],Table52[Net Pay]) -> 229306.25 | G9: AGEGE - AGEGE
A10: =SUBTOTAL(103,Table146[Employee Code]) -> 7 | F10: =SUBTOTAL(109,Table146[NET Salary]) -> 1574138.1
